Workbook

Sheet Summary
A1: LOCATE TRACKER | P1: Status | Q1: Count | R1: _AREAS | S1: _COMPANIES
A2: TOTAL TICKETS | D2: PENDING | G2: CLEARED | J2: EXPIRED | P2: Pending | Q2: {=SUMPRODUCT((TRIM(UPPER(Master!O2:O3859))="PENDING")*1)} -> 276 | R2: {=IFERROR(_xlfn._xlws.SORT(_xlfn.UNIQUE(_xlfn._xlws.FILTER(UPPER(Master!G2:G3859),Master!G2:G3859<>""))),"")} -> CLEARWATER | S2: {=IFERROR(_xlfn._xlws.SORT(_xlfn.UNIQUE(_xlfn._xlws.FILTER(Master!H2:H3859,Master!H2:H3859<>""))),"")} -> A1 Broadband
A3: =COUNTA(Master!C2:C3859) -> 913 | D3: {=SUMPRODUCT((TRIM(UPPER(Master!O2:O3859))="PENDING")*1)} -> 276 | G3: {=SUMPRODUCT((TRIM(UPPER(Master!O2:O3859))="CLEAR")*1)} -> 521 | J3: {=SUMPRODUCT((TRIM(UPPER(Master!O2:O3859))="EXPIRED")*1)} -> 110 | P3: Clear | Q3: {=SUMPRODUCT((TRIM(UPPER(Master!O2:O3859))="CLEAR")*1)} -> 521 | R3: FORT MYERS | S3: Alpha Omega
A4: Active Locate Tickets | D4: Awaiting Completion | G4: Completed Locates | J4: No Action Taken | P4: Expired | Q4: {=SUMPRODUCT((TRIM(UPPER(Master!O2:O3859))="EXPIRED")*1)} -> 110 | R4: LARGO | S4: APT
P5: BRADENTON | Q5: =E27 -> 85 | R5: MANATEE | S5: APT
P6: Area | Q6: Count | R6: MIAMI | S6: APT Communications
P7: BRADENTON | Q7: {=SUMPRODUCT((UPPER(Master!G2:G3859)="BRADENTON")*1)} -> 0 | R7: PINELLAS | S7: ASM
P8: ST. PETERSBURG | Q8: {=SUMPRODUCT((UPPER(Master!G2:G3859)="ST. PETERSBURG")*1)} -> 1 | R8: PORT ST. LUCIE | S8: ASM UTILITIES
P9: PUNTA GORDA | Q9: {=SUMPRODUCT((UPPER(Master!G2:G3859)="PUNTA GORDA")*1)} -> 56 | R9: PORT ST. LUCIE | S9: BICOM
P10: SARASOTA | Q10: {=SUMPRODUCT((UPPER(Master!G2:G3859)="SARASOTA")*1)} -> 0 | R10: PUNTA GORDA | S10: Brothers
P11: PORT CHARLOTTE | Q11: {=SUMPRODUCT((UPPER(Master!G2:G3859)="PORT CHARLOTTE")*1)} -> 0 | R11: SEMINOLE | S11: Brother's
P12: Lightspeed | Q12: =H28 -> 3 | R12: SEMINOLE | S12: GN Systems
P13: Company | Q13: Count | R13: ST. PETERSBURG | S13: HAS GLOBAL
P14: =IFERROR(INDEX(_xlfn.ANCHORARRAY(S2),1),"") -> A1 Broadband | Q14: {=IF(P14="","",SUMPRODUCT((UPPER(Master!H2:H3859)=UPPER(P14))*1))} -> 49 | S14: HD Cable
P15: =IFERROR(INDEX(_xlfn.ANCHORARRAY(S2),2),"") -> Alpha Omega | Q15: {=IF(P15="","",SUMPRODUCT((UPPER(Master!H2:H3859)=UPPER(P15))*1))} -> 16 | S15: ITG
P16: =IFERROR(INDEX(_xlfn.ANCHORARRAY(S2),3),"") -> APT | Q16: {=IF(P16="","",SUMPRODUCT((UPPER(Master!H2:H3859)=UPPER(P16))*1))} -> 11 | S16: ITG COMM
P17: =IFERROR(INDEX(_xlfn.ANCHORARRAY(S2),4),"") -> APT | Q17: {=IF(P17="","",SUMPRODUCT((UPPER(Master!H2:H3859)=UPPER(P17))*1))} -> 6 | S17: ITG COMMS
P18: =IFERROR(INDEX(_xlfn.ANCHORARRAY(S2),5),"") -> APT Communications | Q18: {=IF(P18="","",SUMPRODUCT((UPPER(Master!H2:H3859)=UPPER(P18))*1))} -> 3 | S18: KattleOne
P19: =IFERROR(INDEX(_xlfn.ANCHORARRAY(S2),6),"") -> ASM | Q19: {=IF(P19="","",SUMPRODUCT((UPPER(Master!H2:H3859)=UPPER(P19))*1))} -> 95 | S19: Legant Livings
P20: =IFERROR(INDEX(_xlfn.ANCHORARRAY(S2),7),"") -> ASM UTILITIES | Q20: {=IF(P20="","",SUMPRODUCT((UPPER(Master!H2:H3859)=UPPER(P20))*1))} -> 18 | S20: LOPEZ
P21: =IFERROR(INDEX(_xlfn.ANCHORARRAY(S2),8),"") -> BICOM | Q21: {=IF(P21="","",SUMPRODUCT((UPPER(Master!H2:H3859)=UPPER(P21))*1))} -> 47 | S21: LOPEZ UG
A22: AREA SUMMARY BY STATUS | G22: TICKETS BY COMPANY | P22: =IFERROR(INDEX(_xlfn.ANCHORARRAY(S2),9),"") -> Brothers | Q22: {=IF(P22="","",SUMPRODUCT((UPPER(Master!H2:H3859)=UPPER(P22))*1))} -> 57 | S22: Lopez Underground
A23: Area | B23: Pending | C23: Clear | D23: Expired | E23: Total | G23: Company | H23: Tickets | P23: =IFERROR(INDEX(_xlfn.ANCHORARRAY(S2),10),"") -> Brother's | Q23: {=IF(P23="","",SUMPRODUCT((UPPER(Master!H2:H3859)=UPPER(P23))*1))} -> 12 | S23: LSCG
A24: =IFERROR(INDEX(_xlfn.ANCHORARRAY(R2),1),"") -> CLEARWATER | B24: {=IF(A24="","",SUMPRODUCT((UPPER(Master!$G$2:$G$3859)=A24)*(TRIM(UPPER(Master!$O$2:$O$3859))="PENDING")))} -> 0 | C24: {=IF(A24="","",SUMPRODUCT((UPPER(Master!$G$2:$G$3859)=A24)*(TRIM(UPPER(Master!$O$2:$O$3859))="CLEAR")))} -> 51 | D24: {=IF(A24="","",SUMPRODUCT((UPPER(Master!$G$2:$G$3859)=A24)*(TRIM(UPPER(Master!$O$2:$O$3859))="EXPIRED")))} -> 20 | E24: =IF(A24="","",B24+C24+D24) -> 71 | G24: =IFERROR(INDEX(_xlfn.ANCHORARRAY(S2),1),"") -> A1 Broadband | H24: {=IF(G24="","",SUMPRODUCT((UPPER(Master!H2:H3859)=UPPER(G24))*1))} -> 49 | S24: LSCG / ITG COMM
A25: =IFERROR(INDEX(_xlfn.ANCHORARRAY(R2),2),"") -> FORT MYERS | B25: {=IF(A25="","",SUMPRODUCT((UPPER(Master!$G$2:$G$3859)=A25)*(TRIM(UPPER(Master!$O$2:$O$3859))="PENDING")))} -> 93 | C25: {=IF(A25="","",SUMPRODUCT((UPPER(Master!$G$2:$G$3859)=A25)*(TRIM(UPPER(Master!$O$2:$O$3859))="CLEAR")))} -> 142 | D25: {=IF(A25="","",SUMPRODUCT((UPPER(Master!$G$2:$G$3859)=A25)*(TRIM(UPPER(Master!$O$2:$O$3859))="EXPIRED")))} -> 18 | E25: =IF(A25="","",B25+C25+D25) -> 253 | G25: =IFERROR(INDEX(_xlfn.ANCHORARRAY(S2),2),"") -> Alpha Omega | H25: {=IF(G25="","",SUMPRODUCT((UPPER(Master!H2:H3859)=UPPER(G25))*1))} -> 16 | S25: NIA
A26: =IFERROR(INDEX(_xlfn.ANCHORARRAY(R2),3),"") -> LARGO | B26: {=IF(A26="","",SUMPRODUCT((UPPER(Master!$G$2:$G$3859)=A26)*(TRIM(UPPER(Master!$O$2:$O$3859))="PENDING")))} -> 9 | C26: {=IF(A26="","",SUMPRODUCT((UPPER(Master!$G$2:$G$3859)=A26)*(TRIM(UPPER(Master!$O$2:$O$3859))="CLEAR")))} -> 58 | D26: {=IF(A26="","",SUMPRODUCT((UPPER(Master!$G$2:$G$3859)=A26)*(TRIM(UPPER(Master!$O$2:$O$3859))="EXPIRED")))} -> 12 | E26: =IF(A26="","",B26+C26+D26) -> 79 | G26: =IFERROR(INDEX(_xlfn.ANCHORARRAY(S2),3),"") -> APT | H26: {=IF(G26="","",SUMPRODUCT((UPPER(Master!H2:H3859)=UPPER(G26))*1))} -> 11 | S26: North Path
A27: =IFERROR(INDEX(_xlfn.ANCHORARRAY(R2),4),"") -> MANATEE | B27: {=IF(A27="","",SUMPRODUCT((UPPER(Master!$G$2:$G$3859)=A27)*(TRIM(UPPER(Master!$O$2:$O$3859))="PENDING")))} -> 8 | C27: {=IF(A27="","",SUMPRODUCT((UPPER(Master!$G$2:$G$3859)=A27)*(TRIM(UPPER(Master!$O$2:$O$3859))="CLEAR")))} -> 77 | D27: {=IF(A27="","",SUMPRODUCT((UPPER(Master!$G$2:$G$3859)=A27)*(TRIM(UPPER(Master!$O$2:$O$3859))="EXPIRED")))} -> 0 | E27: =IF(A27="","",B27+C27+D27) -> 85 | G27: =IFERROR(INDEX(_xlfn.ANCHORARRAY(S2),4),"") -> APT | H27: {=IF(G27="","",SUMPRODUCT((UPPER(Master!H2:H3859)=UPPER(G27))*1))} -> 6 | S27: Power Connect
A28: =IFERROR(INDEX(_xlfn.ANCHORARRAY(R2),5),"") -> MIAMI | B28: {=IF(A28="","",SUMPRODUCT((UPPER(Master!$G$2:$G$3859)=A28)*(TRIM(UPPER(Master!$O$2:$O$3859))="PENDING")))} -> 7 | C28: {=IF(A28="","",SUMPRODUCT((UPPER(Master!$G$2:$G$3859)=A28)*(TRIM(UPPER(Master!$O$2:$O$3859))="CLEAR")))} -> 34 | D28: {=IF(A28="","",SUMPRODUCT((UPPER(Master!$G$2:$G$3859)=A28)*(TRIM(UPPER(Master!$O$2:$O$3859))="EXPIRED")))} -> 0 | E28: =IF(A28="","",B28+C28+D28) -> 41 | G28: =IFERROR(INDEX(_xlfn.ANCHORARRAY(S2),5),"") -> APT Communications | H28: {=IF(G28="","",SUMPRODUCT((UPPER(Master!H2:H3859)=UPPER(G28))*1))} -> 3 | S28: R & F
A29: =IFERROR(INDEX(_xlfn.ANCHORARRAY(R2),6),"") -> PINELLAS | B29: {=IF(A29="","",SUMPRODUCT((UPPER(Master!$G$2:$G$3859)=A29)*(TRIM(UPPER(Master!$O$2:$O$3859))="PENDING")))} -> 19 | C29: {=IF(A29="","",SUMPRODUCT((UPPER(Master!$G$2:$G$3859)=A29)*(TRIM(UPPER(Master!$O$2:$O$3859))="CLEAR")))} -> 30 | D29: {=IF(A29="","",SUMPRODUCT((UPPER(Master!$G$2:$G$3859)=A29)*(TRIM(UPPER(Master!$O$2:$O$3859))="EXPIRED")))} -> 10 | E29: =IF(A29="","",B29+C29+D29) -> 59 | G29: =IFERROR(INDEX(_xlfn.ANCHORARRAY(S2),6),"") -> ASM | H29: {=IF(G29="","",SUMPRODUCT((UPPER(Master!H2:H3859)=UPPER(G29))*1))} -> 95 | S29: Randy's Utilities
A30: =IFERROR(INDEX(_xlfn.ANCHORARRAY(R2),7),"") -> PORT ST. LUCIE | B30: {=IF(A30="","",SUMPRODUCT((UPPER(Master!$G$2:$G$3859)=A30)*(TRIM(UPPER(Master!$O$2:$O$3859))="PENDING")))} -> 1 | C30: {=IF(A30="","",SUMPRODUCT((UPPER(Master!$G$2:$G$3859)=A30)*(TRIM(UPPER(Master!$O$2:$O$3859))="CLEAR")))} -> 0 | D30: {=IF(A30="","",SUMPRODUCT((UPPER(Master!$G$2:$G$3859)=A30)*(TRIM(UPPER(Master!$O$2:$O$3859))="EXPIRED")))} -> 0 | E30: =IF(A30="","",B30+C30+D30) -> 1 | G30: =IFERROR(INDEX(_xlfn.ANCHORARRAY(S2),7),"") -> ASM UTILITIES | H30: {=IF(G30="","",SUMPRODUCT((UPPER(Master!H2:H3859)=UPPER(G30))*1))} -> 18 | S30: RDA
A31: =IFERROR(INDEX(_xlfn.ANCHORARRAY(R2),8),"") -> PORT ST. LUCIE | B31: {=IF(A31="","",SUMPRODUCT((UPPER(Master!$G$2:$G$3859)=A31)*(TRIM(UPPER(Master!$O$2:$O$3859))="PENDING")))} -> 24 | C31: {=IF(A31="","",SUMPRODUCT((UPPER(Master!$G$2:$G$3859)=A31)*(TRIM(UPPER(Master!$O$2:$O$3859))="CLEAR")))} -> 22 | D31: {=IF(A31="","",SUMPRODUCT((UPPER(Master!$G$2:$G$3859)=A31)*(TRIM(UPPER(Master!$O$2:$O$3859))="EXPIRED")))} -> 0 | E31: =IF(A31="","",B31+C31+D31) -> 46 | G31: =IFERROR(INDEX(_xlfn.ANCHORARRAY(S2),8),"") -> BICOM | H31: {=IF(G31="","",SUMPRODUCT((UPPER(Master!H2:H3859)=UPPER(G31))*1))} -> 47 | S31: RDA Soluntions
A32: =IFERROR(INDEX(_xlfn.ANCHORARRAY(R2),9),"") -> PUNTA GORDA | B32: {=IF(A32="","",SUMPRODUCT((UPPER(Master!$G$2:$G$3859)=A32)*(TRIM(UPPER(Master!$O$2:$O$3859))="PENDING")))} -> 0 | C32: {=IF(A32="","",SUMPRODUCT((UPPER(Master!$G$2:$G$3859)=A32)*(TRIM(UPPER(Master!$O$2:$O$3859))="CLEAR")))} -> 56 | D32: {=IF(A32="","",SUMPRODUCT((UPPER(Master!$G$2:$G$3859)=A32)*(TRIM(UPPER(Master!$O$2:$O$3859))="EXPIRED")))} -> 0 | E32: =IF(A32="","",B32+C32+D32) -> 56 | G32: =IFERROR(INDEX(_xlfn.ANCHORARRAY(S2),9),"") -> Brothers | H32: {=IF(G32="","",SUMPRODUCT((UPPER(Master!H2:H3859)=UPPER(G32))*1))} -> 57 | S32: RDA SOLUTIONS
A33: =IFERROR(INDEX(_xlfn.ANCHORARRAY(R2),10),"") -> SEMINOLE | B33: {=IF(A33="","",SUMPRODUCT((UPPER(Master!$G$2:$G$3859)=A33)*(TRIM(UPPER(Master!$O$2:$O$3859))="PENDING")))} -> 92 | C33: {=IF(A33="","",SUMPRODUCT((UPPER(Master!$G$2:$G$3859)=A33)*(TRIM(UPPER(Master!$O$2:$O$3859))="CLEAR")))} -> 34 | D33: {=IF(A33="","",SUMPRODUCT((UPPER(Master!$G$2:$G$3859)=A33)*(TRIM(UPPER(Master!$O$2:$O$3859))="EXPIRED")))} -> 2 | E33: =IF(A33="","",B33+C33+D33) -> 128 | G33: =IFERROR(INDEX(_xlfn.ANCHORARRAY(S2),10),"") -> Brother's | H33: {=IF(G33="","",SUMPRODUCT((UPPER(Master!H2:H3859)=UPPER(G33))*1))} -> 12 | S33: RESTORING PRO
A34: =IFERROR(INDEX(_xlfn.ANCHORARRAY(R2),11),"") -> SEMINOLE | B34: {=IF(A34="","",SUMPRODUCT((UPPER(Master!$G$2:$G$3859)=A34)*(TRIM(UPPER(Master!$O$2:$O$3859))="PENDING")))} -> 23 | C34: {=IF(A34="","",SUMPRODUCT((UPPER(Master!$G$2:$G$3859)=A34)*(TRIM(UPPER(Master!$O$2:$O$3859))="CLEAR")))} -> 16 | D34: {=IF(A34="","",SUMPRODUCT((UPPER(Master!$G$2:$G$3859)=A34)*(TRIM(UPPER(Master!$O$2:$O$3859))="EXPIRED")))} -> 48 | E34: =IF(A34="","",B34+C34+D34) -> 87 | G34: =IFERROR(INDEX(_xlfn.ANCHORARRAY(S2),11),"") -> GN Systems | H34: {=IF(G34="","",SUMPRODUCT((UPPER(Master!H2:H3859)=UPPER(G34))*1))} -> 53 | S34: SOSA
A35: =IFERROR(INDEX(_xlfn.ANCHORARRAY(R2),12),"") -> ST. PETERSBURG | B35: {=IF(A35="","",SUMPRODUCT((UPPER(Master!$G$2:$G$3859)=A35)*(TRIM(UPPER(Master!$O$2:$O$3859))="PENDING")))} -> 0 | C35: {=IF(A35="","",SUMPRODUCT((UPPER(Master!$G$2:$G$3859)=A35)*(TRIM(UPPER(Master!$O$2:$O$3859))="CLEAR")))} -> 1 | D35: {=IF(A35="","",SUMPRODUCT((UPPER(Master!$G$2:$G$3859)=A35)*(TRIM(UPPER(Master!$O$2:$O$3859))="EXPIRED")))} -> 0 | E35: =IF(A35="","",B35+C35+D35) -> 1 | G35: =IFERROR(INDEX(_xlfn.ANCHORARRAY(S2),12),"") -> HAS GLOBAL | H35: {=IF(G35="","",SUMPRODUCT((UPPER(Master!H2:H3859)=UPPER(G35))*1))} -> 5 | S35: YOSEP
A36: =IFERROR(INDEX(_xlfn.ANCHORARRAY(R2),13),"") | B36: {=IF(A36="","",SUMPRODUCT((UPPER(Master!$G$2:$G$3859)=A36)*(TRIM(UPPER(Master!$O$2:$O$3859))="PENDING")))} | C36: {=IF(A36="","",SUMPRODUCT((UPPER(Master!$G$2:$G$3859)=A36)*(TRIM(UPPER(Master!$O$2:$O$3859))="CLEAR")))} | D36: {=IF(A36="","",SUMPRODUCT((UPPER(Master!$G$2:$G$3859)=A36)*(TRIM(UPPER(Master!$O$2:$O$3859))="EXPIRED")))} | E36: =IF(A36="","",B36+C36+D36) | G36: =IFERROR(INDEX(_xlfn.ANCHORARRAY(S2),13),"") -> HD Cable | H36: {=IF(G36="","",SUMPRODUCT((UPPER(Master!H2:H3859)=UPPER(G36))*1))} -> 9
A37: =IFERROR(INDEX(_xlfn.ANCHORARRAY(R2),14),"") | B37: {=IF(A37="","",SUMPRODUCT((UPPER(Master!$G$2:$G$3859)=A37)*(TRIM(UPPER(Master!$O$2:$O$3859))="PENDING")))} | C37: {=IF(A37="","",SUMPRODUCT((UPPER(Master!$G$2:$G$3859)=A37)*(TRIM(UPPER(Master!$O$2:$O$3859))="CLEAR")))} | D37: {=IF(A37="","",SUMPRODUCT((UPPER(Master!$G$2:$G$3859)=A37)*(TRIM(UPPER(Master!$O$2:$O$3859))="EXPIRED")))} | E37: =IF(A37="","",B37+C37+D37) | G37: =IFERROR(INDEX(_xlfn.ANCHORARRAY(S2),14),"") -> ITG | H37: {=IF(G37="","",SUMPRODUCT((UPPER(Master!H2:H3859)=UPPER(G37))*1))} -> 40
A38: =IFERROR(INDEX(_xlfn.ANCHORARRAY(R2),15),"") | B38: {=IF(A38="","",SUMPRODUCT((UPPER(Master!$G$2:$G$3859)=A38)*(TRIM(UPPER(Master!$O$2:$O$3859))="PENDING")))} | C38: {=IF(A38="","",SUMPRODUCT((UPPER(Master!$G$2:$G$3859)=A38)*(TRIM(UPPER(Master!$O$2:$O$3859))="CLEAR")))} | D38: {=IF(A38="","",SUMPRODUCT((UPPER(Master!$G$2:$G$3859)=A38)*(TRIM(UPPER(Master!$O$2:$O$3859))="EXPIRED")))} | E38: =IF(A38="","",B38+C38+D38) | G38: =IFERROR(INDEX(_xlfn.ANCHORARRAY(S2),15),"") -> ITG COMM | H38: {=IF(G38="","",SUMPRODUCT((UPPER(Master!H2:H3859)=UPPER(G38))*1))} -> 2
A39: TOTALS | B39: =SUMIF(A24:A38,"<>",B24:B38) -> 276 | C39: =SUMIF(A24:A38,"<>",C24:C38) -> 521 | D39: =SUMIF(A24:A38,"<>",D24:D38) -> 110 | E39: =SUMIF(A24:A38,"<>",E24:E38) -> 907 | G39: =IFERROR(INDEX(_xlfn.ANCHORARRAY(S2),16),"") -> ITG COMMS | H39: {=IF(G39="","",SUMPRODUCT((UPPER(Master!H2:H3859)=UPPER(G39))*1))} -> 36
G40: =IFERROR(INDEX(_xlfn.ANCHORARRAY(S2),17),"") -> KattleOne | H40: {=IF(G40="","",SUMPRODUCT((UPPER(Master!H2:H3859)=UPPER(G40))*1))} -> 25
...

Sheet Master
A1: MAP # | B1: PERMIT # | C1: LOCATE TICKET | D1: 2ND TICKET | E1: 3RD TICKET | F1: PHONE NUMBER | G1: AREA | H1: COMPANY NAME | I1: DATE CALLED | J1: DUE DATE | K1: EXPIRE DATE | L1: 1st Call | M1: 2nd Call | N1: 3rd Call | O1: TICKET STATUS | P1: DATE TICKET COMPLETED | Q1: FOOTAGE | R1: NOTES
A2: D-HPP638 | B2: RUP-26-00500 | C2: 149606102 | D2: 202604860 | E2: 230602160 | F2: 727-338-4027 | G2: CLEARWATER | H2: LSCG | I2: 46252 | J2: 46255 | K2: 46283 | O2: Clear
A3: D-HPP638 | B3: RUP-26-00500 | C3: 149605915 | D3: 202604874 | E3: 230602148 | F3: 727-338-4027 | G3: CLEARWATER | H3: LSCG | I3: 46252 | J3: 46255 | K3: 46283 | O3: Clear
A4: D-HPP638 | B4: RUP-26-00500 | C4: 149605949 | D4: 202604889 | E4: 230602138 | F4: 727-338-4027 | G4: CLEARWATER | H4: LSCG | I4: 46252 | J4: 46255 | K4: 46283 | O4: Clear
A5: D-HPP638 | B5: RUP-26-00500 | C5: 149605839 | D5: 202604906 | E5: 230602126 | F5: 727-338-4027 | G5: CLEARWATER | H5: LSCG | I5: 46252 | J5: 46255 | K5: 46283 | O5: Clear
A6: D-HPP638 | B6: RUP-26-00500 | C6: 149605888 | D6: 202604913 | E6: 230602117 | F6: 727-338-4027 | G6: CLEARWATER | H6: LSCG | I6: 46252 | J6: 46255 | K6: 46283 | O6: Clear
A7: D-HPP638 | B7: RUP-26-00500 | C7: 149605739 | D7: 202604925 | E7: 230602109 | F7: 727-338-4027 | G7: CLEARWATER | H7: LSCG | I7: 46252 | J7: 46255 | K7: 46283 | O7: Clear
A8: D-HPP638 | B8: RUP-26-00500 | C8: 149606173 | D8: 202604936 | E8: 230602100 | F8: 727-338-4027 | G8: CLEARWATER | H8: LSCG | I8: 46252 | J8: 46255 | K8: 46283 | O8: Clear
A9: D-HPP638 | B9: RUP-26-00500 | C9: 149606196 | D9: 202604944 | E9: 230602091 | F9: 727-338-4027 | G9: CLEARWATER | H9: LSCG | I9: 46252 | J9: 46255 | K9: 46283 | O9: Clear
A10: D-HPP637 | B10: RUP-26-00528 | C10: 204603967 | D10: 230602812 | F10: 813-394-1039 | G10: CLEARWATER | H10: LSCG | I10: 46252 | J10: 46255 | K10: 46283 | O10: Clear
A11: D-HPP637 | B11: RUP-26-00528 | C11: 204604010 | D11: 230602781 | F11: 813-394-1039 | G11: CLEARWATER | H11: LSCG | I11: 46252 | J11: 46255 | K11: 46283 | O11: Clear
A12: D-HPP637 | B12: RUP-26-00528 | C12: 204604089 | D12: 230602414 | F12: 813-394-1039 | G12: CLEARWATER | H12: LSCG | I12: 46252 | J12: 46255 | K12: 46283 | O12: Clear
A13: D-HPP637 | B13: RUP-26-00528 | C13: 204604138 | D13: 230602401 | F13: 813-394-1039 | G13: CLEARWATER | H13: LSCG | I13: 46252 | J13: 46255 | K13: 46283 | O13: Clear
A14: D-HPP637 | B14: RUP-26-00528 | C14: 204604171 | D14: 230602386 | F14: 813-394-1039 | G14: CLEARWATER | H14: LSCG | I14: 46252 | J14: 46255 | K14: 46283 | O14: Clear
A15: D-HPP637 | B15: RUP-26-00528 | C15: 204604190 | D15: 230602370 | F15: 813-394-1039 | G15: CLEARWATER | H15: LSCG | I15: 46252 | J15: 46255 | K15: 46283 | O15: Clear
A16: D-HPP637 | B16: RUP-26-00528 | C16: 204604339 | D16: 230602296 | F16: 813-394-1039 | G16: CLEARWATER | H16: LSCG | I16: 46252 | J16: 46255 | K16: 46283 | O16: EXPIRED
A17: D-HLC511 | B17: RUP-26-01300 | C17: 205600663 | D17: 239600561 | F17: 813-394-1039 | G17: CLEARWATER | H17: LSCG | I17: 46227 | J17: 46230 | K17: 46258 | O17: Clear
A18: D-HLC511 | B18: RUP-26-01300 | C18: 205600565 | D18: 239600566 | F18: 813-394-1039 | G18: CLEARWATER | H18: LSCG | I18: 46227 | J18: 46230 | K18: 46258 | O18: Clear
A19: D-HLC511 | B19: RUP-26-01300 | C19: 205600476 | D19: 239600570 | F19: 813-394-1039 | G19: CLEARWATER | H19: LSCG | I19: 46227 | J19: 46230 | K19: 46258 | O19: Clear
A20: D-HLC511 | B20: RUP-26-01300 | C20: 205600464 | D20: 239600578 | F20: 813-394-1039 | G20: CLEARWATER | H20: LSCG | I20: 46227 | J20: 46230 | K20: 46258 | O20: Clear
A21: D-HPP608 | B21: RUP-26-00353 | C21: 203600145 | D21: 229601556 | F21: 863-212-6570 | G21: CLEARWATER | H21: LSCG | I21: 46251 | J21: 46254 | K21: 46282 | O21: Clear | R21: per james h this is job is complete
A22: D-HPP608 | B22: RUP-26-00353 | C22: 203600153 | D22: 229601586 | F22: 863-212-6570 | G22: CLEARWATER | H22: LSCG | I22: 46251 | J22: 46254 | K22: 46282 | O22: Clear
A23: D-HPP608 | B23: RUP-26-00353 | C23: 203600157 | D23: 229601597 | F23: 863-212-6570 | G23: CLEARWATER | H23: LSCG | I23: 46251 | J23: 46254 | K23: 46282 | O23: Clear
A24: D-HPP608 | B24: RUP-26-00353 | C24: 203600162 | D24: 229601564 | F24: 863-212-6570 | G24: CLEARWATER | H24: LSCG | I24: 46251 | J24: 46254 | K24: 46282 | O24: Clear
A25: D-HPP608 | B25: RUP-26-00353 | C25: 203600168 | D25: 229601573 | F25: 863-212-6570 | G25: CLEARWATER | H25: LSCG | I25: 46251 | J25: 46254 | K25: 46282 | O25: Clear
A26: D-HPP608 | B26: RUP-26-00353 | C26: 203600174 | D26: 229601604 | F26: 863-212-6570 | G26: CLEARWATER | H26: LSCG | I26: 46251 | J26: 46254 | K26: 46282 | O26: Clear
A27: D-HPP608 | B27: RUP-26-00353 | C27: 203600178 | D27: 229601536 | F27: 863-212-6570 | G27: CLEARWATER | H27: LSCG | I27: 46251 | J27: 46254 | K27: 46282 | O27: Clear
A28: FB-HOE401-V4 | C28: 210601640 | F28: 727-338-4027 | G28: MANATEE | H28: LSCG | I28: 46232 | J28: 46235 | K28: 46263 | O28: Clear
A29: FB-HOE401-V6 | C29: 210603499 | F29: 727-338-4027 | G29: MANATEE | H29: LSCG | I29: 46232 | J29: 46235 | K29: 46263 | O29: Clear
A30: D-HLC505 | B30: RUP-26-01305 | C30: 210609327 | F30: 813-494-6583 | G30: Largo | H30: NIA | I30: 46232 | J30: 46235 | K30: 46263 | O30: Clear
A31: D-HLC505 | B31: RUP-26-01305 | C31: 210609318 | F31: 813-494-6583 | G31: Largo | H31: NIA | I31: 46232 | J31: 46235 | K31: 46263 | O31: Clear
A32: D-HLC505 | B32: RUP-26-01305 | C32: 210609312 | F32: 813-494-6583 | G32: Largo | H32: NIA | I32: 46232 | J32: 46235 | K32: 46263 | O32: Clear
A33: D-HLC505 | B33: RUP-26-01305 | C33: 210609305 | F33: 813-494-6583 | G33: Largo | H33: NIA | I33: 46232 | J33: 46235 | K33: 46263 | O33: Clear
A34: D-HLC505 | B34: RUP-26-01305 | C34: 210609298 | F34: 813-494-6583 | G34: Largo | H34: NIA | I34: 46232 | J34: 46235 | K34: 46263 | O34: Clear
A35: D-HLC505 | B35: RUP-26-01305 | C35: 210609286 | F35: 813-494-6583 | G35: Largo | H35: NIA | I35: 46232 | J35: 46235 | K35: 46263 | O35: Clear
A36: D-HLC505 | B36: RUP-26-01305 | C36: 210609283 | F36: 813-494-6583 | G36: Largo | H36: NIA | I36: 46232 | J36: 46235 | K36: 46263 | O36: Clear
A37: D-HLC505 | B37: RUP-26-01305 | C37: 210608880 | F37: 813-494-6583 | G37: Largo | H37: NIA | I37: 46232 | J37: 46235 | K37: 46263 | O37: Clear
A38: D-HLC505 | B38: RUP-26-01305 | C38: 210608873 | F38: 813-494-6583 | G38: Largo | H38: NIA | I38: 46232 | J38: 46235 | K38: 46263 | O38: Clear
A39: D-HLC505 | B39: RUP-26-01305 | C39: 210608863 | F39: 813-494-6583 | G39: Largo | H39: NIA | I39: 46232 | J39: 46235 | K39: 46263 | O39: Clear
A40: FB-HTG279 | B40: ROW2026-01941 | C40: 215604240 | F40: 727-338-4027 | G40: FORT MYERS | H40: LSCG | I40: 46237 | J40: 46240 | K40: 46268 | O40: Clear
...

Sheet Naples
A1: MAP # | B1: LOCATE TICKET | C1: AREA | D1: DATE CALLED | E1: COMPANY NAME | F1: NOTES
A2: BHCD-FEF-01-W | B2: 56506013 | C2: Ft Meyers | D2: 45716 | E2: Diathena
A3: BHCD-FEF-01-W | B3: 56506218 | C3: Ft Meyers | D3: 45716 | E3: Diathena
A4: BHCD-FEF-01-E | B4: 56506367 | C4: Ft Meyers | D4: 45716 | E4: Diathena
A5: BCD-FDF-01-EH | B5: 56506513 | C5: Ft Meyers | D5: 45716 | E5: Diathena
A6: BCD-FDF-01-EH | B6: 56506567 | C6: Ft Meyers | D6: 45716 | E6: Diathena

Sheet Pinellas-St Petesburg
A1: MAP # | B1: LOCATE TICKET | C1: AREA | D1: DATE CALLED | E1: COMPANY NAME | F1: NOTES
A2: FB-HDH02A | B2: 10507009 | C2: ST PETE | D2: 45658 | E2: Juan Garcia
A3: FB-HDH02A | B3: 10507037 | C3: ST PETE | D3: 45658 | E3: Juan Garcia
A4: FB-HDH02A | B4: 10507027 | C4: ST PETE | D4: 45658 | E4: Juan Garcia
A5: FB-HDH02A | B5: 10507008 | C5: ST PETE | D5: 45658 | E5: Juan Garcia
A6: FB-HDH02A | B6: 10507102 | C6: ST PETE | D6: 45658 | E6: Juan Garcia
A7: FB-HDH02A | B7: 10507007 | C7: ST PETE | D7: 45658 | E7: Juan Garcia
A8: FB-HDH02A | B8: 10507014 | C8: ST PETE | D8: 45658 | E8: Juan Garcia
A9: FB-HDH02A | B9: 9504725 | C9: ST PETE | D9: 45666 | E9: REYCAMP | F9: REYCAMP..NORTH SIDE OF 29TH AVE N , STARTING AT 47TH ST N EAST TO 46TH ST N
A10: FB-HDH02A | B10: 9502380 | C10: ST PETE | D10: 45666 | E10: REYCAMP | F10: REYCAMP..WEST SIDE OF 47TH ST N STARTING AT 36TH AVE N GOING SOUTH TO 33RD AVE N...PC1343 HAS DECLARED EXTRAORDINARY CIRCUMSTANCES
A11: FB-HDH02A | B11: 9501187 | C11: ST PETE | D11: 45666 | E11: REYCAMP | F11: REYCAMP...WEST AND SOUTH SIDE OF PROPERTY 301 S DALE MABRY...MCIU01, TAMP04, VW2324 HAS DECLARED EXTRAORDINARY CIRCUMSTANCES
A12: FB-HDH02A | B12: 10507009 | C12: ST PETE | D12: 45667 | E12: Juan Garcia | F12: Missing Frontier and Power Locates
A13: FB-HDH02A | B13: 10507014 | C13: ST PETE | D13: 45667 | E13: Juan Garcia | F13: Missing Frontier and Power Locates
A14: FB-HDH02A | B14: 10507027 | C14: ST PETE | D14: 45667 | E14: Juan Garcia | F14: Missing Frontier and Power Locates
A15: FB-HDH02A | B15: 10507008 | C15: ST PETE | D15: 45667 | E15: Juan Garcia | F15: Missing Frontier and Power Locates
A16: FB-HDH02A | B16: 10507003 | C16: ST PETE | D16: 45667 | E16: Juan Garcia | F16: Missing Frontier and Power Locates
A17: FB-HDH02A | B17: 8509919 | C17: ST PETE | D17: 45668 | E17: REYCAMP | F17: REYCAMP-WEST SIDE OF 51ST N, STARTING AT 28TH AVE N TO 30TH AVE N
A18: FB-HDH02A | B18: 8509573 | C18: ST PETE | D18: 45668 | E18: REYCAMP | F18: WEST SIDE OF UTTICA ST N , STARTING AT 38TH AVE N GOING SOUTH TO 36TH AVE N...PC1343 HAS DECLARED EXTRAORDINARY CIRCUMSTANCES
A19: FB-HDH02A | B19: 14509553 | C19: ST PETE | D19: 45671 | E19: REYCAMP | F19: REYCAMP. SOUTH SIDE OF 36TH AVE N , STARTING AT 45TH ST N WEST TO 46TH ST N....PC1343 HAS DECLARED EXTRAORDINARY CIRCUMSTANCES
A20: FB-HDH02A | B20: 14509533 | C20: ST PETE | D20: 45671 | E20: REYCAMP | F20: REYCAMP..WEST SIDE OF 45TH ST N..32ND ST N GOING NORTH TO 36TH AVE N...
... A26: FB-HDH02A | B26: 14509450 | C26: ST PETE | D26: 45671 | E26: REYCAMP | F26: REYCAMP..BOTH SIDES OF30TH AVE N...STARTING 51ST ST N GOING WEST TO 52ND ST N
A27: FB-HDH02A | B27: 17507042 | C27: PINELLAS | D27: 45674 | E27: JUAN GARCIA
A28: FB-HDH02A | B28: 17507045 | C28: PINELLAS | D28: 45674 | E28: JUAN GARCIA
A29: FB-HDH02A | B29: 17507052 | C29: PINELLAS | D29: 45674 | E29: JUAN GARCIA
A30: FB-HDH02A | B30: 17507041 | C30: PINELLAS | D30: 45674 | E30: JUAN GARCIA
A31: FB-HDH02A | B31: 17507047 | C31: PINELLAS | D31: 45674 | E31: JUAN GARCIA
A32: FB-HDH02A | B32: 17507044 | C32: PINELLAS | D32: 45674 | E32: JUAN GARCIA
A33: FB-HDH02A | B33: 18500390 | C33: PINELLAS | D33: 45674 | E33: JUAN GARCIA
A34: FB-HDH02A | B34: 18500398 | C34: PINELLAS | D34: 45674 | E34: JUAN GARCIA
A35: FB-HDH02A | B35: 18500403 | C35: PINELLAS | D35: 45674 | E35: JUAN GARCIA
A36: D-HDH66 | B36: 18500300 | C36: PINELLAS | D36: 45675 | E36: REYCAMP
A37: D-HDH66 | B37: 18500282 | C37: PINELLAS | D37: 45675 | E37: REYCAMP
A38: D-HDH66 | B38: 18500294 | C38: PINELLAS | D38: 45675 | E38: REYCAMP
... A94: FB-HDH02A | B94: 23507104 | C94: PINELLAS / ST. PETE | D94: 45680 | E94: Bartlett Fiber
A95: D-HDH34 | B95: 29507354 | C95: ST PETE | D95: 45684 | E95: Lightspeed In-House | F95: 5025 35TH AVE N
A96: D-HDH34 | B96: 28507244 | C96: ST PETE | D96: 45684 | E96: Lightspeed In-House | F96: 30TH AVE N,41ST ST N
A97: D-HDH34 | B97: 28506894 | C97: ST PETE | D97: 45684 | E97: Lightspeed In-House | F97: 30TH AVE N,40TH ST N
A98: D-HDH34 | B98: 28506868 | C98: ST PETE | D98: 45684 | E98: Lightspeed In-House | F98: 30TH AVE N,38TH ST N
A99: D-HDH34 | B99: 28506849 | C99: ST PETE | D99: 45684 | E99: Lightspeed In-House | F99: 30TH AVE N,37TH ST N
A100: D-HDH34 | B100: 28506322 | C100: ST PETE | D100: 45684 | E100: Lightspeed In-House | F100: 30TH AVE N,37TH ST N
...

Sheet Sarasota

Sheet Completed locates
A1: MAP # | B1: PERMIT # | C1: LOCATE TICKET | D1: 2ND TICKET | E1: 3RD TICKET | F1: PHONE NUMBER | G1: AREA | H1: COMPANY NAME | I1: DATE CALLED | J1: DUE DATE | K1: EXPIRE DATE | L1: 1st Call | M1: 2nd Call | N1: 3rd Call | O1: TICKET STATUS | P1: DATE TICKET COMPLETED | Q1: FOOTAGE | R1: NOTES
A2: D-HWP713 | C2: 38505194 | G2: LAKELAND | H2: Brothers | I2: 45695 | R2: Griffin Rd & Kalt Dr
A3: D-HWP713 | C3: 38505213 | G3: LAKELAND | H3: Brothers | I3: 45695 | R3: Kalt Dr & Griffin Rd
A4: D-HWP105 | C4: 50507609 | G4: LAKELAND | H4: BROTHERS | I4: 45707 | R4: N LAKE AVE,E PARKER ST
A5: D-HWP105 | C5: 50507859 | G5: LAKELAND | H5: BROTHERS | I5: 45707 | R5: E MAGNOLIA ST,N STELLA AVE,N LAKE AVE
A6: rev 000259-golden wings mhp | C6: 21507562 | G6: LAKELAND | H6: Lightspeed In-House | I6: 45678
A7: rev 000259-golden wings mhp | C7: 21507565 | G7: LAKELAND | H7: Lightspeed In-House | I7: 45678
A8: rev 000259-golden wings mhp | C8: 21507568 | G8: LAKELAND | H8: Lightspeed In-House | I8: 45678
A9: rev 000259-golden wings mhp | C9: 21507569 | G9: LAKELAND | H9: Lightspeed In-House | I9: 45678
A10: rev 000259-golden wings mhp | C10: 21507570 | G10: LAKELAND | H10: Lightspeed In-House | I10: 45678
A11: D-H0222B | C11: 30503735 | G11: ST PETERSBURG | H11: Brothers | I11: 45686 | R11: 2ND ST S,56TH AVE S,60TH AVE S
A12: D-H0222B | C12: 30503776 | G12: ST PETERSBURG | H12: Brothers | I12: 45686 | R12: 59TH AVE S,BAHAMA SHORES DR S,3RD ST S
A13: D-H0222B | C13: 30503798 | G13: ST PETERSBURG | H13: Brothers | I13: 45686 | R13: 60TH AVE S,BAHAMA SHORES DR S,3RD ST S
A14: D-H0222B | C14: 30503821 | G14: ST PETERSBURG | H14: Brothers | I14: 45686 | R14: BAHAMA SHORES DR S,58TH AVE S,62ND AVE S
A15: D-H0222B | C15: 30503763 | G15: ST PETERSBURG | H15: Brothers | I15: 45686 | R15: 58TH AVE S,BAHAMA SHORES DR S,3RD ST S
A16: D-H0222B | C16: 35505134 | G16: ST PETERSBURG | H16: Brothers | I16: 45691 | R16: BAHAMA SHORES DR S,58TH AVE S,62ND AVE S
A17: D-H0222B | C17: 35505087 | G17: ST PETERSBURG | H17: Brothers | I17: 45691 | R17: 60TH AVE S,BAHAMA SHORES DR S,3RD ST S
A18: D-H0222B | C18: 35504960 | G18: ST PETERSBURG | H18: Brothers | I18: 45691 | R18: 3RD ST S,59TH AVE S,60TH AVE S
A19: D-H0222B | C19: 35504929 | G19: ST PETERSBURG | H19: Brothers | I19: 45691 | R19: 2ND ST S,56TH AVE S,60TH AVE S
A20: D-H0222B | C20: 35504891 | G20: ST PETERSBURG | H20: Brothers | I20: 45691 | R20: 59TH AVE S,BAHAMA SHORES DR S,3RD ST S
A21: D-H0222B | C21: 35504415 | G21: ST PETERSBURG | H21: Brothers | I21: 45691 | R21: 58TH AVE S,BAHAMA SHORES DR S,3RD ST S
A22: D-H0223D | C22: 35506238 | G22: ST PETERSBURG | H22: Brothers | I22: 45691 | R22: 51ST AVE S,7TH ST S,6TH ST S
... A153: D-H0223A | C153: 35501743 | G153: ST PETERSBURG | H153: Bartlett Fiber | I153: 45692 | R153: (N)NE-NW, 52ND AVE S/8TH ST S-7TH ST S
A154: D-HDH66 | C154: 18500300 | G154: ST PETERSBURG | H154: REYCAMP | I154: 45675
A155: D-HDH66 | C155: 18500282 | G155: ST PETERSBURG | H155: REYCAMP | I155: 45675
A156: D-HDH66 | C156: 18500294 | G156: ST PETERSBURG | H156: REYCAMP | I156: 45675
A157: D-HDH66 | C157: 18500272 | G157: ST PETERSBURG | H157: REYCAMP | I157: 45675
A158: D-HDH66 | C158: 18500276 | G158: ST PETERSBURG | H158: REYCAMP | I158: 45675
A159: D-HDH66 | C159: 21507602 | G159: ST PETERSBURG | H159: Bartlett Fiber | I159: 45679
A160: D-HDH66 | C160: 22500600 | G160: ST PETERSBURG | H160: Bartlett Fiber | I160: 45679
A161: D-HDH66 | C161: 22500667 | G161: ST PETERSBURG | H161: Bartlett Fiber | I161: 45679
A162: D-HDH66 | C162: 22500718 | G162: ST PETERSBURG | H162: Bartlett Fiber | I162: 45679
A163: D-HDH66 | C163: 48503822 | G163: ST PETERSBURG | H163: Bartlett Fiber | I163: 45705 | R163: (W)SW-NW, 53RD ST N/37TH AVE N-34TH AVE N
A164: D-HDH66 | C164: 48503862 | G164: ST PETERSBURG | H164: Bartlett Fiber | I164: 45705 | R164: RD+(N,DRWY) 3690 53RD ST N
A165: D-HDH66 | C165: 48503899 | G165: ST PETERSBURG | H165: Bartlett Fiber | I165: 45705 | R165: RD+(W,S), 53RD ST N & 36TH AVE N
A166: D-HDH66 | C166: 48503938 | G166: ST PETERSBURG | H166: Bartlett Fiber | I166: 45705 | R166: RD+(W,N), 53RD ST N & 35TH TER N
A167: D-HDH66 | C167: 48504049 | G167: ST PETERSBURG | H167: Bartlett Fiber | I167: 45705 | R167: (S)SW-SW, 36TH AVE N/53RD ST N-52ND ST N
A168: D-HDH66 | C168: 48504019 | G168: ST PETERSBURG | H168: Bartlett Fiber | I168: 45705 | R168: RD+x2, 5298, 5284 & 5270, 5256 36TH AVE N
A169: D-HDH66 | C169: 48504110 | G169: ST PETERSBURG | H169: Bartlett Fiber | I169: 45705 | R169: RD+, 5242, 5228 36TH AVE N
A170: D-HDH66 | C170: 48504133 | G170: ST PETERSBURG | H170: Bartlett Fiber | I170: 45705 | R170: RD+(E PROP LINE), 5214 36TH AVE N
...
