Workbook

Sheet Dashboard
A1: TILLMAN PROJECT DASHBOARD
A2: ="Last Updated: "&TEXT(NOW(),"MM/DD/YYYY h:mm AM/PM") -> Last Updated: 10/10/2026 1:51 PM
A4: FILTERS
A5: Area Filter: | B5: All | C5: Status Filter: | D5: All | E5: Vendor Filter: | F5: All | G5: Supervisor Filter: | H5: All
A7: KEY PERFORMANCE INDICATORS — ACTIVE PROJECTS
A9: Total Active Projects | D9: Total Planned Footage (ft) | H9: Footage Completed (ft) | L9: Footage Remaining (ft)
A10: {=SUMPRODUCT(((('Tillman UG Footage'!P2:P209="In Process")+('Tillman UG Footage'!P2:P209="Not Started")+('Tillman UG Footage'!P2:P209="Locates Called"))>0)*1*--(IF($B$5="All",TRUE,'Tillman UG Footage'!B2:B209=$B$5))*--(IF($D$5="All",TRUE,'Tillman UG Footage'!P2:P209=$D$5))*--(IF($F$5="All",TRUE,ISNUMBER(FIND($F$5,'Tillman UG Footage'!D2:D209&" "))))*--(IF($H$5="All",TRUE,ISNUMBER(FIND($H$5,'Tillman UG Footage'!F2:F209&" ")))))} -> 173 | D10: {=SUMPRODUCT(((('Tillman UG Footage'!P2:P209="In Process")+('Tillman UG Footage'!P2:P209="Not Started")+('Tillman UG Footage'!P2:P209="Locates Called"))>0)*1*--(IF($B$5="All",TRUE,'Tillman UG Footage'!B2:B209=$B$5))*--(IF($D$5="All",TRUE,'Tillman UG Footage'!P2:P209=$D$5))*--(IF($F$5="All",TRUE,ISNUMBER(FIND($F$5,'Tillman UG Footage'!D2:D209&" "))))*--(IF($H$5="All",TRUE,ISNUMBER(FIND($H$5,'Tillman UG Footage'!F2:F209&" "))))*(IF(ISNUMBER('Tillman UG Footage'!V2:V209),'Tillman UG Footage'!V2:V209,0)))} -> 1055483 | H10: {=SUMPRODUCT(((('Tillman UG Footage'!P2:P209="In Process")+('Tillman UG Footage'!P2:P209="Not Started")+('Tillman UG Footage'!P2:P209="Locates Called"))>0)*1*--(IF($B$5="All",TRUE,'Tillman UG Footage'!B2:B209=$B$5))*--(IF($D$5="All",TRUE,'Tillman UG Footage'!P2:P209=$D$5))*--(IF($F$5="All",TRUE,ISNUMBER(FIND($F$5,'Tillman UG Footage'!D2:D209&" "))))*--(IF($H$5="All",TRUE,ISNUMBER(FIND($H$5,'Tillman UG Footage'!F2:F209&" "))))*(IF(ISNUMBER('Tillman UG Footage'!W2:W209),'Tillman UG Footage'!W2:W209,0)))} -> 193973 | L10: {=SUMPRODUCT(((('Tillman UG Footage'!P2:P209="In Process")+('Tillman UG Footage'!P2:P209="Not Started")+('Tillman UG Footage'!P2:P209="Locates Called"))>0)*1*--(IF($B$5="All",TRUE,'Tillman UG Footage'!B2:B209=$B$5))*--(IF($D$5="All",TRUE,'Tillman UG Footage'!P2:P209=$D$5))*--(IF($F$5="All",TRUE,ISNUMBER(FIND($F$5,'Tillman UG Footage'!D2:D209&" "))))*--(IF($H$5="All",TRUE,ISNUMBER(FIND($H$5,'Tillman UG Footage'!F2:F209&" "))))*(IF(ISNUMBER('Tillman UG Footage'!X2:X209),'Tillman UG Footage'!X2:X209,0)))} -> 870533
A12: Overall % Complete | D12: Total SOW Est. Cost | H12: Total HHP | L12: Projects Pending PW
A13: =IFERROR(H10/D10,0) -> 0.18377653 | D13: {=SUMPRODUCT(((('Tillman UG Footage'!P2:P209="In Process")+('Tillman UG Footage'!P2:P209="Not Started")+('Tillman UG Footage'!P2:P209="Locates Called"))>0)*1*--(IF($B$5="All",TRUE,'Tillman UG Footage'!B2:B209=$B$5))*--(IF($D$5="All",TRUE,'Tillman UG Footage'!P2:P209=$D$5))*--(IF($F$5="All",TRUE,ISNUMBER(FIND($F$5,'Tillman UG Footage'!D2:D209&" "))))*--(IF($H$5="All",TRUE,ISNUMBER(FIND($H$5,'Tillman UG Footage'!F2:F209&" "))))*(IF(ISNUMBER('Tillman UG Footage'!N2:N209),'Tillman UG Footage'!N2:N209,0)))} -> 9986420.6 | H13: {=SUMPRODUCT(((('Tillman UG Footage'!P2:P209="In Process")+('Tillman UG Footage'!P2:P209="Not Started")+('Tillman UG Footage'!P2:P209="Locates Called"))>0)*1*--(IF($B$5="All",TRUE,'Tillman UG Footage'!B2:B209=$B$5))*--(IF($D$5="All",TRUE,'Tillman UG Footage'!P2:P209=$D$5))*--(IF($F$5="All",TRUE,ISNUMBER(FIND($F$5,'Tillman UG Footage'!D2:D209&" "))))*--(IF($H$5="All",TRUE,ISNUMBER(FIND($H$5,'Tillman UG Footage'!F2:F209&" "))))*(IF(ISNUMBER('Tillman UG Footage'!H2:H209),'Tillman UG Footage'!H2:H209,0)))} -> 10586 | L13: =COUNTA('Pending Resto-COP Packages'!A10:A113) -> 103
A15: PROJECTS BY AREA | F15: CONSTRUCTION STATUS | K15: PERMIT STATUS
A16: Area | B16: Projects | C16: Footage | D16: % Complete | F16: Status | G16: Count | H16: Footage | I16: Est. Cost | K16: Permit Status | L16: Count | M16: % of Total
A17: St Petersburg | B17: {=SUMPRODUCT(((('Tillman UG Footage'!P2:P209="In Process")+('Tillman UG Footage'!P2:P209="Not Started")+('Tillman UG Footage'!P2:P209="Locates Called"))>0)*1*--('Tillman UG Footage'!B2:B209="St Petersburg")*--(IF($D$5="All",TRUE,'Tillman UG Footage'!P2:P209=$D$5))*--(IF($F$5="All",TRUE,ISNUMBER(FIND($F$5,'Tillman UG Footage'!D2:D209&" "))))*--(IF($H$5="All",TRUE,ISNUMBER(FIND($H$5,'Tillman UG Footage'!F2:F209&" ")))))} -> 1 | C17: {=SUMPRODUCT(((('Tillman UG Footage'!P2:P209="In Process")+('Tillman UG Footage'!P2:P209="Not Started")+('Tillman UG Footage'!P2:P209="Locates Called"))>0)*1*--('Tillman UG Footage'!B2:B209="St Petersburg")*--(IF($D$5="All",TRUE,'Tillman UG Footage'!P2:P209=$D$5))*--(IF($F$5="All",TRUE,ISNUMBER(FIND($F$5,'Tillman UG Footage'!D2:D209&" "))))*--(IF($H$5="All",TRUE,ISNUMBER(FIND($H$5,'Tillman UG Footage'!F2:F209&" "))))*(IF(ISNUMBER('Tillman UG Footage'!V2:V209),'Tillman UG Footage'!V2:V209,0)))} -> 6182 | D17: {=IFERROR(SUMPRODUCT(((('Tillman UG Footage'!P2:P209="In Process")+('Tillman UG Footage'!P2:P209="Not Started")+('Tillman UG Footage'!P2:P209="Locates Called"))>0)*1*--('Tillman UG Footage'!B2:B209="St Petersburg")*--(IF($D$5="All",TRUE,'Tillman UG Footage'!P2:P209=$D$5))*--(IF($F$5="All",TRUE,ISNUMBER(FIND($F$5,'Tillman UG Footage'!D2:D209&" "))))*--(IF($H$5="All",TRUE,ISNUMBER(FIND($H$5,'Tillman UG Footage'!F2:F209&" "))))*(IF(ISNUMBER('Tillman UG Footage'!W2:W209),'Tillman UG Footage'!W2:W209,0)))/C17,0)} -> 0.95422193 | F17: In Process | G17: {=SUMPRODUCT(--(IF($B$5="All",TRUE,'Tillman UG Footage'!B2:B209=$B$5))*--('Tillman UG Footage'!P2:P209="In Process")*--(IF($F$5="All",TRUE,ISNUMBER(FIND($F$5,'Tillman UG Footage'!D2:D209&" "))))*--(IF($H$5="All",TRUE,ISNUMBER(FIND($H$5,'Tillman UG Footage'!F2:F209&" ")))))} -> 30 | H17: {=SUMPRODUCT(--(IF($B$5="All",TRUE,'Tillman UG Footage'!B2:B209=$B$5))*--('Tillman UG Footage'!P2:P209="In Process")*--(IF($F$5="All",TRUE,ISNUMBER(FIND($F$5,'Tillman UG Footage'!D2:D209&" "))))*--(IF($H$5="All",TRUE,ISNUMBER(FIND($H$5,'Tillman UG Footage'!F2:F209&" "))))*(IF(ISNUMBER('Tillman UG Footage'!V2:V209),'Tillman UG Footage'!V2:V209,0)))} -> 201366 | I17: {=SUMPRODUCT(--(IF($B$5="All",TRUE,'Tillman UG Footage'!B2:B209=$B$5))*--('Tillman UG Footage'!P2:P209="In Process")*--(IF($F$5="All",TRUE,ISNUMBER(FIND($F$5,'Tillman UG Footage'!D2:D209&" "))))*--(IF($H$5="All",TRUE,ISNUMBER(FIND($H$5,'Tillman UG Footage'!F2:F209&" "))))*(IF(ISNUMBER('Tillman UG Footage'!N2:N209),'Tillman UG Footage'!N2:N209,0)))} -> 1781324.4 | K17: Received | L17: {=SUMPRODUCT(((('Tillman UG Footage'!P2:P209="In Process")+('Tillman UG Footage'!P2:P209="Not Started")+('Tillman UG Footage'!P2:P209="Locates Called"))>0)*1*--(IF($B$5="All",TRUE,'Tillman UG Footage'!B2:B209=$B$5))*--(IF($D$5="All",TRUE,'Tillman UG Footage'!P2:P209=$D$5))*--(IF($F$5="All",TRUE,ISNUMBER(FIND($F$5,'Tillman UG Footage'!D2:D209&" "))))*--(IF($H$5="All",TRUE,ISNUMBER(FIND($H$5,'Tillman UG Footage'!F2:F209&" "))))*--('Tillman UG Footage'!J2:J209="Received"))} -> 98 | M17: =IFERROR(L17/SUM(L17:L19),0) -> 0.56647399
A18: Lakeland | B18: {=SUMPRODUCT(((('Tillman UG Footage'!P2:P209="In Process")+('Tillman UG Footage'!P2:P209="Not Started")+('Tillman UG Footage'!P2:P209="Locates Called"))>0)*1*--('Tillman UG Footage'!B2:B209="Lakeland")*--(IF($D$5="All",TRUE,'Tillman UG Footage'!P2:P209=$D$5))*--(IF($F$5="All",TRUE,ISNUMBER(FIND($F$5,'Tillman UG Footage'!D2:D209&" "))))*--(IF($H$5="All",TRUE,ISNUMBER(FIND($H$5,'Tillman UG Footage'!F2:F209&" ")))))} -> 2 | C18: {=SUMPRODUCT(((('Tillman UG Footage'!P2:P209="In Process")+('Tillman UG Footage'!P2:P209="Not Started")+('Tillman UG Footage'!P2:P209="Locates Called"))>0)*1*--('Tillman UG Footage'!B2:B209="Lakeland")*--(IF($D$5="All",TRUE,'Tillman UG Footage'!P2:P209=$D$5))*--(IF($F$5="All",TRUE,ISNUMBER(FIND($F$5,'Tillman UG Footage'!D2:D209&" "))))*--(IF($H$5="All",TRUE,ISNUMBER(FIND($H$5,'Tillman UG Footage'!F2:F209&" "))))*(IF(ISNUMBER('Tillman UG Footage'!V2:V209),'Tillman UG Footage'!V2:V209,0)))} -> 4107 | D18: {=IFERROR(SUMPRODUCT(((('Tillman UG Footage'!P2:P209="In Process")+('Tillman UG Footage'!P2:P209="Not Started")+('Tillman UG Footage'!P2:P209="Locates Called"))>0)*1*--('Tillman UG Footage'!B2:B209="Lakeland")*--(IF($D$5="All",TRUE,'Tillman UG Footage'!P2:P209=$D$5))*--(IF($F$5="All",TRUE,ISNUMBER(FIND($F$5,'Tillman UG Footage'!D2:D209&" "))))*--(IF($H$5="All",TRUE,ISNUMBER(FIND($H$5,'Tillman UG Footage'!F2:F209&" "))))*(IF(ISNUMBER('Tillman UG Footage'!W2:W209),'Tillman UG Footage'!W2:W209,0)))/C18,0)} -> 0.95641588 | F18: Not Started | G18: {=SUMPRODUCT(--(IF($B$5="All",TRUE,'Tillman UG Footage'!B2:B209=$B$5))*--('Tillman UG Footage'!P2:P209="Not Started")*--(IF($F$5="All",TRUE,ISNUMBER(FIND($F$5,'Tillman UG Footage'!D2:D209&" "))))*--(IF($H$5="All",TRUE,ISNUMBER(FIND($H$5,'Tillman UG Footage'!F2:F209&" ")))))} -> 92 | H18: {=SUMPRODUCT(--(IF($B$5="All",TRUE,'Tillman UG Footage'!B2:B209=$B$5))*--('Tillman UG Footage'!P2:P209="Not Started")*--(IF($F$5="All",TRUE,ISNUMBER(FIND($F$5,'Tillman UG Footage'!D2:D209&" "))))*--(IF($H$5="All",TRUE,ISNUMBER(FIND($H$5,'Tillman UG Footage'!F2:F209&" "))))*(IF(ISNUMBER('Tillman UG Footage'!V2:V209),'Tillman UG Footage'!V2:V209,0)))} -> 534834 | I18: {=SUMPRODUCT(--(IF($B$5="All",TRUE,'Tillman UG Footage'!B2:B209=$B$5))*--('Tillman UG Footage'!P2:P209="Not Started")*--(IF($F$5="All",TRUE,ISNUMBER(FIND($F$5,'Tillman UG Footage'!D2:D209&" "))))*--(IF($H$5="All",TRUE,ISNUMBER(FIND($H$5,'Tillman UG Footage'!F2:F209&" "))))*(IF(ISNUMBER('Tillman UG Footage'!N2:N209),'Tillman UG Footage'!N2:N209,0)))} -> 4613883.2 | K18: Pending | L18: {=SUMPRODUCT(((('Tillman UG Footage'!P2:P209="In Process")+('Tillman UG Footage'!P2:P209="Not Started")+('Tillman UG Footage'!P2:P209="Locates Called"))>0)*1*--(IF($B$5="All",TRUE,'Tillman UG Footage'!B2:B209=$B$5))*--(IF($D$5="All",TRUE,'Tillman UG Footage'!P2:P209=$D$5))*--(IF($F$5="All",TRUE,ISNUMBER(FIND($F$5,'Tillman UG Footage'!D2:D209&" "))))*--(IF($H$5="All",TRUE,ISNUMBER(FIND($H$5,'Tillman UG Footage'!F2:F209&" "))))*--('Tillman UG Footage'!J2:J209="Pending"))} -> 73 | M18: =IFERROR(L18/SUM(L17:L19),0) -> 0.42196532
A19: Bradenton | B19: {=SUMPRODUCT(((('Tillman UG Footage'!P2:P209="In Process")+('Tillman UG Footage'!P2:P209="Not Started")+('Tillman UG Footage'!P2:P209="Locates Called"))>0)*1*--('Tillman UG Footage'!B2:B209="Bradenton")*--(IF($D$5="All",TRUE,'Tillman UG Footage'!P2:P209=$D$5))*--(IF($F$5="All",TRUE,ISNUMBER(FIND($F$5,'Tillman UG Footage'!D2:D209&" "))))*--(IF($H$5="All",TRUE,ISNUMBER(FIND($H$5,'Tillman UG Footage'!F2:F209&" ")))))} -> 11 | C19: {=SUMPRODUCT(((('Tillman UG Footage'!P2:P209="In Process")+('Tillman UG Footage'!P2:P209="Not Started")+('Tillman UG Footage'!P2:P209="Locates Called"))>0)*1*--('Tillman UG Footage'!B2:B209="Bradenton")*--(IF($D$5="All",TRUE,'Tillman UG Footage'!P2:P209=$D$5))*--(IF($F$5="All",TRUE,ISNUMBER(FIND($F$5,'Tillman UG Footage'!D2:D209&" "))))*--(IF($H$5="All",TRUE,ISNUMBER(FIND($H$5,'Tillman UG Footage'!F2:F209&" "))))*(IF(ISNUMBER('Tillman UG Footage'!V2:V209),'Tillman UG Footage'!V2:V209,0)))} -> 52836 | D19: {=IFERROR(SUMPRODUCT(((('Tillman UG Footage'!P2:P209="In Process")+('Tillman UG Footage'!P2:P209="Not Started")+('Tillman UG Footage'!P2:P209="Locates Called"))>0)*1*--('Tillman UG Footage'!B2:B209="Bradenton")*--(IF($D$5="All",TRUE,'Tillman UG Footage'!P2:P209=$D$5))*--(IF($F$5="All",TRUE,ISNUMBER(FIND($F$5,'Tillman UG Footage'!D2:D209&" "))))*--(IF($H$5="All",TRUE,ISNUMBER(FIND($H$5,'Tillman UG Footage'!F2:F209&" "))))*(IF(ISNUMBER('Tillman UG Footage'!W2:W209),'Tillman UG Footage'!W2:W209,0)))/C19,0)} -> 0.20232417 | F19: Locates Called | G19: {=SUMPRODUCT(--(IF($B$5="All",TRUE,'Tillman UG Footage'!B2:B209=$B$5))*--('Tillman UG Footage'!P2:P209="Locates Called")*--(IF($F$5="All",TRUE,ISNUMBER(FIND($F$5,'Tillman UG Footage'!D2:D209&" "))))*--(IF($H$5="All",TRUE,ISNUMBER(FIND($H$5,'Tillman UG Footage'!F2:F209&" ")))))} -> 51 | H19: {=SUMPRODUCT(--(IF($B$5="All",TRUE,'Tillman UG Footage'!B2:B209=$B$5))*--('Tillman UG Footage'!P2:P209="Locates Called")*--(IF($F$5="All",TRUE,ISNUMBER(FIND($F$5,'Tillman UG Footage'!D2:D209&" "))))*--(IF($H$5="All",TRUE,ISNUMBER(FIND($H$5,'Tillman UG Footage'!F2:F209&" "))))*(IF(ISNUMBER('Tillman UG Footage'!V2:V209),'Tillman UG Footage'!V2:V209,0)))} -> 319283 | I19: {=SUMPRODUCT(--(IF($B$5="All",TRUE,'Tillman UG Footage'!B2:B209=$B$5))*--('Tillman UG Footage'!P2:P209="Locates Called")*--(IF($F$5="All",TRUE,ISNUMBER(FIND($F$5,'Tillman UG Footage'!D2:D209&" "))))*--(IF($H$5="All",TRUE,ISNUMBER(FIND($H$5,'Tillman UG Footage'!F2:F209&" "))))*(IF(ISNUMBER('Tillman UG Footage'!N2:N209),'Tillman UG Footage'!N2:N209,0)))} -> 3591212.8 | K19: Not Required | L19: {=SUMPRODUCT(((('Tillman UG Footage'!P2:P209="In Process")+('Tillman UG Footage'!P2:P209="Not Started")+('Tillman UG Footage'!P2:P209="Locates Called"))>0)*1*--(IF($B$5="All",TRUE,'Tillman UG Footage'!B2:B209=$B$5))*--(IF($D$5="All",TRUE,'Tillman UG Footage'!P2:P209=$D$5))*--(IF($F$5="All",TRUE,ISNUMBER(FIND($F$5,'Tillman UG Footage'!D2:D209&" "))))*--(IF($H$5="All",TRUE,ISNUMBER(FIND($H$5,'Tillman UG Footage'!F2:F209&" "))))*--('Tillman UG Footage'!J2:J209="Not Required"))} -> 2 | M19: =IFERROR(L19/SUM(L17:L19),0) -> 0.011560694
A20: Fort Myers | B20: {=SUMPRODUCT(((('Tillman UG Footage'!P2:P209="In Process")+('Tillman UG Footage'!P2:P209="Not Started")+('Tillman UG Footage'!P2:P209="Locates Called"))>0)*1*--('Tillman UG Footage'!B2:B209="Fort Myers")*--(IF($D$5="All",TRUE,'Tillman UG Footage'!P2:P209=$D$5))*--(IF($F$5="All",TRUE,ISNUMBER(FIND($F$5,'Tillman UG Footage'!D2:D209&" "))))*--(IF($H$5="All",TRUE,ISNUMBER(FIND($H$5,'Tillman UG Footage'!F2:F209&" ")))))} -> 26 | C20: {=SUMPRODUCT(((('Tillman UG Footage'!P2:P209="In Process")+('Tillman UG Footage'!P2:P209="Not Started")+('Tillman UG Footage'!P2:P209="Locates Called"))>0)*1*--('Tillman UG Footage'!B2:B209="Fort Myers")*--(IF($D$5="All",TRUE,'Tillman UG Footage'!P2:P209=$D$5))*--(IF($F$5="All",TRUE,ISNUMBER(FIND($F$5,'Tillman UG Footage'!D2:D209&" "))))*--(IF($H$5="All",TRUE,ISNUMBER(FIND($H$5,'Tillman UG Footage'!F2:F209&" "))))*(IF(ISNUMBER('Tillman UG Footage'!V2:V209),'Tillman UG Footage'!V2:V209,0)))} -> 169836 | D20: {=IFERROR(SUMPRODUCT(((('Tillman UG Footage'!P2:P209="In Process")+('Tillman UG Footage'!P2:P209="Not Started")+('Tillman UG Footage'!P2:P209="Locates Called"))>0)*1*--('Tillman UG Footage'!B2:B209="Fort Myers")*--(IF($D$5="All",TRUE,'Tillman UG Footage'!P2:P209=$D$5))*--(IF($F$5="All",TRUE,ISNUMBER(FIND($F$5,'Tillman UG Footage'!D2:D209&" "))))*--(IF($H$5="All",TRUE,ISNUMBER(FIND($H$5,'Tillman UG Footage'!F2:F209&" "))))*(IF(ISNUMBER('Tillman UG Footage'!W2:W209),'Tillman UG Footage'!W2:W209,0)))/C20,0)} -> 0.36343296 | F20: Completed | G20: {=SUMPRODUCT(--(IF($B$5="All",TRUE,'Tillman UG Footage'!B2:B209=$B$5))*--('Tillman UG Footage'!P2:P209="Completed")*--(IF($F$5="All",TRUE,ISNUMBER(FIND($F$5,'Tillman UG Footage'!D2:D209&" "))))*--(IF($H$5="All",TRUE,ISNUMBER(FIND($H$5,'Tillman UG Footage'!F2:F209&" ")))))} -> 6 | H20: {=SUMPRODUCT(--(IF($B$5="All",TRUE,'Tillman UG Footage'!B2:B209=$B$5))*--('Tillman UG Footage'!P2:P209="Completed")*--(IF($F$5="All",TRUE,ISNUMBER(FIND($F$5,'Tillman UG Footage'!D2:D209&" "))))*--(IF($H$5="All",TRUE,ISNUMBER(FIND($H$5,'Tillman UG Footage'!F2:F209&" "))))*IF(ISNUMBER('Tillman UG Footage'!V2:V209),'Tillman UG Footage'!V2:V209,0))} -> 47138 | I20: {=SUMPRODUCT(--(IF($B$5="All",TRUE,'Tillman UG Footage'!B2:B209=$B$5))*--('Tillman UG Footage'!P2:P209="Completed")*--(IF($F$5="All",TRUE,ISNUMBER(FIND($F$5,'Tillman UG Footage'!D2:D209&" "))))*--(IF($H$5="All",TRUE,ISNUMBER(FIND($H$5,'Tillman UG Footage'!F2:F209&" "))))*IF(ISNUMBER('Tillman UG Footage'!N2:N209),'Tillman UG Footage'!N2:N209,0))} -> 572325 | K20: TOTAL | L20: =SUM(L17:L19) -> 173 | M20: 1
A21: Port Charlotte | B21: {=SUMPRODUCT(((('Tillman UG Footage'!P2:P209="In Process")+('Tillman UG Footage'!P2:P209="Not Started")+('Tillman UG Footage'!P2:P209="Locates Called"))>0)*1*--('Tillman UG Footage'!B2:B209="Port Charlotte")*--(IF($D$5="All",TRUE,'Tillman UG Footage'!P2:P209=$D$5))*--(IF($F$5="All",TRUE,ISNUMBER(FIND($F$5,'Tillman UG Footage'!D2:D209&" "))))*--(IF($H$5="All",TRUE,ISNUMBER(FIND($H$5,'Tillman UG Footage'!F2:F209&" ")))))} -> 4 | C21: {=SUMPRODUCT(((('Tillman UG Footage'!P2:P209="In Process")+('Tillman UG Footage'!P2:P209="Not Started")+('Tillman UG Footage'!P2:P209="Locates Called"))>0)*1*--('Tillman UG Footage'!B2:B209="Port Charlotte")*--(IF($D$5="All",TRUE,'Tillman UG Footage'!P2:P209=$D$5))*--(IF($F$5="All",TRUE,ISNUMBER(FIND($F$5,'Tillman UG Footage'!D2:D209&" "))))*--(IF($H$5="All",TRUE,ISNUMBER(FIND($H$5,'Tillman UG Footage'!F2:F209&" "))))*(IF(ISNUMBER('Tillman UG Footage'!V2:V209),'Tillman UG Footage'!V2:V209,0)))} -> 10662 | D21: {=IFERROR(SUMPRODUCT(((('Tillman UG Footage'!P2:P209="In Process")+('Tillman UG Footage'!P2:P209="Not Started")+('Tillman UG Footage'!P2:P209="Locates Called"))>0)*1*--('Tillman UG Footage'!B2:B209="Port Charlotte")*--(IF($D$5="All",TRUE,'Tillman UG Footage'!P2:P209=$D$5))*--(IF($F$5="All",TRUE,ISNUMBER(FIND($F$5,'Tillman UG Footage'!D2:D209&" "))))*--(IF($H$5="All",TRUE,ISNUMBER(FIND($H$5,'Tillman UG Footage'!F2:F209&" "))))*(IF(ISNUMBER('Tillman UG Footage'!W2:W209),'Tillman UG Footage'!W2:W209,0)))/C21,0)} -> 0.55946352 | F21: TOTAL | G21: =SUM(G17:G20) -> 179 | H21: =SUM(H17:H20) -> 1102621 | I21: =SUM(I17:I20) -> 10558746
A22: Naples | B22: {=SUMPRODUCT(((('Tillman UG Footage'!P2:P209="In Process")+('Tillman UG Footage'!P2:P209="Not Started")+('Tillman UG Footage'!P2:P209="Locates Called"))>0)*1*--('Tillman UG Footage'!B2:B209="Naples")*--(IF($D$5="All",TRUE,'Tillman UG Footage'!P2:P209=$D$5))*--(IF($F$5="All",TRUE,ISNUMBER(FIND($F$5,'Tillman UG Footage'!D2:D209&" "))))*--(IF($H$5="All",TRUE,ISNUMBER(FIND($H$5,'Tillman UG Footage'!F2:F209&" ")))))} -> 0 | C22: {=SUMPRODUCT(((('Tillman UG Footage'!P2:P209="In Process")+('Tillman UG Footage'!P2:P209="Not Started")+('Tillman UG Footage'!P2:P209="Locates Called"))>0)*1*--('Tillman UG Footage'!B2:B209="Naples")*--(IF($D$5="All",TRUE,'Tillman UG Footage'!P2:P209=$D$5))*--(IF($F$5="All",TRUE,ISNUMBER(FIND($F$5,'Tillman UG Footage'!D2:D209&" "))))*--(IF($H$5="All",TRUE,ISNUMBER(FIND($H$5,'Tillman UG Footage'!F2:F209&" "))))*(IF(ISNUMBER('Tillman UG Footage'!V2:V209),'Tillman UG Footage'!V2:V209,0)))} -> 0 | D22: {=IFERROR(SUMPRODUCT(((('Tillman UG Footage'!P2:P209="In Process")+('Tillman UG Footage'!P2:P209="Not Started")+('Tillman UG Footage'!P2:P209="Locates Called"))>0)*1*--('Tillman UG Footage'!B2:B209="Naples")*--(IF($D$5="All",TRUE,'Tillman UG Footage'!P2:P209=$D$5))*--(IF($F$5="All",TRUE,ISNUMBER(FIND($F$5,'Tillman UG Footage'!D2:D209&" "))))*--(IF($H$5="All",TRUE,ISNUMBER(FIND($H$5,'Tillman UG Footage'!F2:F209&" "))))*(IF(ISNUMBER('Tillman UG Footage'!W2:W209),'Tillman UG Footage'!W2:W209,0)))/C22,0)} -> 0
A23: Kissimmee | B23: {=SUMPRODUCT(((('Tillman UG Footage'!P2:P209="In Process")+('Tillman UG Footage'!P2:P209="Not Started")+('Tillman UG Footage'!P2:P209="Locates Called"))>0)*1*--('Tillman UG Footage'!B2:B209="Kissimmee")*--(IF($D$5="All",TRUE,'Tillman UG Footage'!P2:P209=$D$5))*--(IF($F$5="All",TRUE,ISNUMBER(FIND($F$5,'Tillman UG Footage'!D2:D209&" "))))*--(IF($H$5="All",TRUE,ISNUMBER(FIND($H$5,'Tillman UG Footage'!F2:F209&" ")))))} -> 54 | C23: {=SUMPRODUCT(((('Tillman UG Footage'!P2:P209="In Process")+('Tillman UG Footage'!P2:P209="Not Started")+('Tillman UG Footage'!P2:P209="Locates Called"))>0)*1*--('Tillman UG Footage'!B2:B209="Kissimmee")*--(IF($D$5="All",TRUE,'Tillman UG Footage'!P2:P209=$D$5))*--(IF($F$5="All",TRUE,ISNUMBER(FIND($F$5,'Tillman UG Footage'!D2:D209&" "))))*--(IF($H$5="All",TRUE,ISNUMBER(FIND($H$5,'Tillman UG Footage'!F2:F209&" "))))*(IF(ISNUMBER('Tillman UG Footage'!V2:V209),'Tillman UG Footage'!V2:V209,0)))} -> 379857 | D23: {=IFERROR(SUMPRODUCT(((('Tillman UG Footage'!P2:P209="In Process")+('Tillman UG Footage'!P2:P209="Not Started")+('Tillman UG Footage'!P2:P209="Locates Called"))>0)*1*--('Tillman UG Footage'!B2:B209="Kissimmee")*--(IF($D$5="All",TRUE,'Tillman UG Footage'!P2:P209=$D$5))*--(IF($F$5="All",TRUE,ISNUMBER(FIND($F$5,'Tillman UG Footage'!D2:D209&" "))))*--(IF($H$5="All",TRUE,ISNUMBER(FIND($H$5,'Tillman UG Footage'!F2:F209&" "))))*(IF(ISNUMBER('Tillman UG Footage'!W2:W209),'Tillman UG Footage'!W2:W209,0)))/C23,0)} -> 0.038611899
A24: Miami | B24: {=SUMPRODUCT(((('Tillman UG Footage'!P2:P209="In Process")+('Tillman UG Footage'!P2:P209="Not Started")+('Tillman UG Footage'!P2:P209="Locates Called"))>0)*1*--('Tillman UG Footage'!B2:B209="Miami")*--(IF($D$5="All",TRUE,'Tillman UG Footage'!P2:P209=$D$5))*--(IF($F$5="All",TRUE,ISNUMBER(FIND($F$5,'Tillman UG Footage'!D2:D209&" "))))*--(IF($H$5="All",TRUE,ISNUMBER(FIND($H$5,'Tillman UG Footage'!F2:F209&" ")))))} -> 2 | C24: {=SUMPRODUCT(((('Tillman UG Footage'!P2:P209="In Process")+('Tillman UG Footage'!P2:P209="Not Started")+('Tillman UG Footage'!P2:P209="Locates Called"))>0)*1*--('Tillman UG Footage'!B2:B209="Miami")*--(IF($D$5="All",TRUE,'Tillman UG Footage'!P2:P209=$D$5))*--(IF($F$5="All",TRUE,ISNUMBER(FIND($F$5,'Tillman UG Footage'!D2:D209&" "))))*--(IF($H$5="All",TRUE,ISNUMBER(FIND($H$5,'Tillman UG Footage'!F2:F209&" "))))*(IF(ISNUMBER('Tillman UG Footage'!V2:V209),'Tillman UG Footage'!V2:V209,0)))} -> 16213 | D24: {=IFERROR(SUMPRODUCT(((('Tillman UG Footage'!P2:P209="In Process")+('Tillman UG Footage'!P2:P209="Not Started")+('Tillman UG Footage'!P2:P209="Locates Called"))>0)*1*--('Tillman UG Footage'!B2:B209="Miami")*--(IF($D$5="All",TRUE,'Tillman UG Footage'!P2:P209=$D$5))*--(IF($F$5="All",TRUE,ISNUMBER(FIND($F$5,'Tillman UG Footage'!D2:D209&" "))))*--(IF($H$5="All",TRUE,ISNUMBER(FIND($H$5,'Tillman UG Footage'!F2:F209&" "))))*(IF(ISNUMBER('Tillman UG Footage'!W2:W209),'Tillman UG Footage'!W2:W209,0)))/C24,0)} -> 0.84086844
A25: Pinellas | B25: {=SUMPRODUCT(((('Tillman UG Footage'!P2:P209="In Process")+('Tillman UG Footage'!P2:P209="Not Started")+('Tillman UG Footage'!P2:P209="Locates Called"))>0)*1*--('Tillman UG Footage'!B2:B209="Pinellas")*--(IF($D$5="All",TRUE,'Tillman UG Footage'!P2:P209=$D$5))*--(IF($F$5="All",TRUE,ISNUMBER(FIND($F$5,'Tillman UG Footage'!D2:D209&" "))))*--(IF($H$5="All",TRUE,ISNUMBER(FIND($H$5,'Tillman UG Footage'!F2:F209&" ")))))} -> 30 | C25: {=SUMPRODUCT(((('Tillman UG Footage'!P2:P209="In Process")+('Tillman UG Footage'!P2:P209="Not Started")+('Tillman UG Footage'!P2:P209="Locates Called"))>0)*1*--('Tillman UG Footage'!B2:B209="Pinellas")*--(IF($D$5="All",TRUE,'Tillman UG Footage'!P2:P209=$D$5))*--(IF($F$5="All",TRUE,ISNUMBER(FIND($F$5,'Tillman UG Footage'!D2:D209&" "))))*--(IF($H$5="All",TRUE,ISNUMBER(FIND($H$5,'Tillman UG Footage'!F2:F209&" "))))*(IF(ISNUMBER('Tillman UG Footage'!V2:V209),'Tillman UG Footage'!V2:V209,0)))} -> 177702 | D25: {=IFERROR(SUMPRODUCT(((('Tillman UG Footage'!P2:P209="In Process")+('Tillman UG Footage'!P2:P209="Not Started")+('Tillman UG Footage'!P2:P209="Locates Called"))>0)*1*--('Tillman UG Footage'!B2:B209="Pinellas")*--(IF($D$5="All",TRUE,'Tillman UG Footage'!P2:P209=$D$5))*--(IF($F$5="All",TRUE,ISNUMBER(FIND($F$5,'Tillman UG Footage'!D2:D209&" "))))*--(IF($H$5="All",TRUE,ISNUMBER(FIND($H$5,'Tillman UG Footage'!F2:F209&" "))))*(IF(ISNUMBER('Tillman UG Footage'!W2:W209),'Tillman UG Footage'!W2:W209,0)))/C25,0)} -> 0.080032864
A26: TOTAL | B26: =SUM(B17:B25) -> 130 | C26: =SUM(C17:C25) -> 817395 | D26: =IFERROR(H10/D10,0) -> 0.18377653
A28: TOP VENDORS | F28: SUPERVISOR ASSIGNMENTS | R28: HELPER – Vendors (auto) | S28: Active | T28: Completed | U28: Total
A29: Vendor | B29: Active | C29: Completed | D29: Total | F29: Supervisor | G29: Active | H29: Completed | I29: Total | R29: {=_xlfn._xlws.SORT(_xlfn.UNIQUE(_xlfn.VSTACK(_xlfn._xlws.FILTER(TRIM('Tillman UG Footage'!D2:D209),(TRIM('Tillman UG Footage'!D2:D209)<>"")*(TRIM('Tillman UG Footage'!D2:D209)<>"Vendor Assignment")),_xlfn._xlws.FILTER(TRIM('Pending Resto-COP Packages'!D2:D101),(TRIM('Pending Resto-COP Packages'!D2:D101)<>"")*(TRIM('Pending Resto-COP Packages'!D2:D101)<>"Vendor Assignment")))))} -> A1 Broadband | S29: {=_xlfn.BYROW(_xlfn.ANCHORARRAY(R29),_xlfn.LAMBDA(_xlpm.v,COUNTIF('Tillman UG Footage'!D:D,"*"&_xlpm.v&"*")))} -> 2 | T29: {=_xlfn.BYROW(_xlfn.ANCHORARRAY(R29),_xlfn.LAMBDA(_xlpm.v,COUNTIF('Pending Resto-COP Packages'!D:D,"*"&_xlpm.v&"*")))} -> 1 | U29: {=_xlfn.ANCHORARRAY(S29)+_xlfn.ANCHORARRAY(T29)} -> 3
A30: Lightspeed In-House | B30: =COUNTIF('Tillman UG Footage'!D:D,"*Lightspeed*") -> 2 | C30: =COUNTIF('Pending Resto-COP Packages'!D:D,"*Lightspeed*") -> 15 | D30: =B30+C30 -> 17 | F30: Joshua | G30: =COUNTIFS('Tillman UG Footage'!F:F,"*"&F30&"*",'Tillman UG Footage'!B:B,"<>AREA") -> 26 | H30: =COUNTIF('Pending Resto-COP Packages'!F:F,"*"&F30&"*") -> 41 | I30: =G30+H30 -> 67 | R30: AG QUALITY | S30: 1 | T30: 0 | U30: 1
A31: GN Systems | B31: =COUNTIF('Tillman UG Footage'!D:D,"*GN Systems*") -> 4 | C31: =COUNTIF('Pending Resto-COP Packages'!D:D,"*GN Systems*") -> 6 | D31: =B31+C31 -> 10 | F31: Cody | G31: =COUNTIFS('Tillman UG Footage'!F:F,"*"&F31&"*",'Tillman UG Footage'!B:B,"<>AREA") -> 1 | H31: =COUNTIF('Pending Resto-COP Packages'!F:F,"*"&F31&"*") -> 3 | I31: =G31+H31 -> 4 | R31: AGN | S31: 6 | T31: 5 | U31: 11
A32: North Path | B32: =COUNTIF('Tillman UG Footage'!D:D,"*North Path*") -> 10 | C32: =COUNTIF('Pending Resto-COP Packages'!D:D,"*North Path*") -> 8 | D32: =B32+C32 -> 18 | F32: Travis | G32: =COUNTIFS('Tillman UG Footage'!F:F,"*"&F32&"*",'Tillman UG Footage'!B:B,"<>AREA") -> 0 | H32: =COUNTIF('Pending Resto-COP Packages'!F:F,"*"&F32&"*") -> 0 | I32: =G32+H32 -> 0 | R32: AGN Undergrounds | S32: 2 | T32: 0 | U32: 2
A33: Brothers | B33: =COUNTIF('Tillman UG Footage'!D:D,"*Brother*") -> 8 | C33: =COUNTIF('Pending Resto-COP Packages'!D:D,"*Brother*") -> 16 | D33: =B33+C33 -> 24 | F33: Johnnie | G33: =COUNTIFS('Tillman UG Footage'!F:F,"*"&F33&"*",'Tillman UG Footage'!B:B,"<>AREA") -> 6 | H33: =COUNTIF('Pending Resto-COP Packages'!F:F,"*"&F33&"*") -> 10 | I33: =G33+H33 -> 16 | R33: Alpha Omega | S33: 3 | T33: 2 | U33: 5
A34: Kattle One | B34: =COUNTIF('Tillman UG Footage'!D:D,"*Kattle One*") -> 5 | C34: =COUNTIF('Pending Resto-COP Packages'!D:D,"*Kattle One*") -> 0 | D34: =B34+C34 -> 5 | F34: Miguel | G34: =COUNTIFS('Tillman UG Footage'!F:F,"*"&F34&"*",'Tillman UG Footage'!B:B,"<>AREA") -> 7 | H34: =COUNTIF('Pending Resto-COP Packages'!F:F,"*"&F34&"*") -> 2 | I34: =G34+H34 -> 9 | R34: AMB Communications | S34: 3 | T34: 0 | U34: 3
A35: Yosep AER | B35: =COUNTIF('Tillman UG Footage'!D:D,"*Yosep AER*") -> 2 | C35: =COUNTIF('Pending Resto-COP Packages'!D:D,"*Yosep AER*") -> 7 | D35: =B35+C35 -> 9 | F35: Eric | G35: =COUNTIFS('Tillman UG Footage'!F:F,"*"&F35&"*",'Tillman UG Footage'!B:B,"<>AREA") -> 1 | H35: =COUNTIF('Pending Resto-COP Packages'!F:F,"*"&F35&"*") -> 0 | I35: =G35+H35 -> 1 | R35: APT Communications | S35: 4 | T35: 3 | U35: 7
A36: APT Communications | B36: =COUNTIF('Tillman UG Footage'!D:D,"*APT Communications*") -> 4 | C36: =COUNTIF('Pending Resto-COP Packages'!D:D,"*APT Communications*") -> 3 | D36: =B36+C36 -> 7 | F36: Anthony | G36: =COUNTIFS('Tillman UG Footage'!F:F,"*"&F36&"*",'Tillman UG Footage'!B:B,"<>AREA") -> 4 | H36: =COUNTIF('Pending Resto-COP Packages'!F:F,"*"&F36&"*") -> 11 | I36: =G36+H36 -> 15 | R36: APT Communications / New Gen Unlimited | S36: 1 | T36: 0 | U36: 1
A37: Lopez Underground | B37: =COUNTIF('Tillman UG Footage'!D:D,"*Lopez*") -> 7 | C37: =COUNTIF('Pending Resto-COP Packages'!D:D,"*Lopez*") -> 16 | D37: =B37+C37 -> 23 | F37: James | G37: =COUNTIFS('Tillman UG Footage'!F:F,"*"&F37&"*",'Tillman UG Footage'!B:B,"<>AREA") -> 0 | H37: =COUNTIF('Pending Resto-COP Packages'!F:F,"*"&F37&"*") -> 0 | I37: =G37+H37 -> 0 | R37: APT Communications/Kattleone | S37: 0 | T37: 1 | U37: 1
A38: Power Connect | B38: =COUNTIF('Tillman UG Footage'!D:D,"*Power Connect*") -> 7 | C38: =COUNTIF('Pending Resto-COP Packages'!D:D,"*Power Connect*") -> 5 | D38: =B38+C38 -> 12 | F38: Marcelo | G38: =COUNTIFS('Tillman UG Footage'!F:F,"*"&F38&"*",'Tillman UG Footage'!B:B,"<>AREA") -> 1 | H38: =COUNTIF('Pending Resto-COP Packages'!F:F,"*"&F38&"*") -> 5 | I38: =G38+H38 -> 6 | R38: APT Communications/North Path | S38: 1 | T38: 0 | U38: 1
A39: HAS Global | B39: =COUNTIF('Tillman UG Footage'!D:D,"*HAS Global*") -> 1 | C39: =COUNTIF('Pending Resto-COP Packages'!D:D,"*HAS Global*") -> 2 | D39: =B39+C39 -> 3 | F39: Matthew Nunes | G39: =COUNTIFS('Tillman UG Footage'!F:F,"*"&F39&"*",'Tillman UG Footage'!B:B,"<>AREA") -> 2 | H39: =COUNTIF('Pending Resto-COP Packages'!F:F,"*"&F39&"*") -> 6 | I39: =G39+H39 -> 8 | R39: ASM | S39: 3 | T39: 4 | U39: 7
A40: Legant | B40: =COUNTIF('Tillman UG Footage'!D:D,"*Legant*") -> 4 | C40: =COUNTIF('Pending Resto-COP Packages'!D:D,"*Legant*") -> 2 | D40: =B40+C40 -> 6 | F40: Treyvon | G40: =COUNTIFS('Tillman UG Footage'!F:F,"*"&F40&"*",'Tillman UG Footage'!B:B,"<>AREA") -> 8 | H40: =COUNTIF('Pending Resto-COP Packages'!F:F,"*"&F40&"*") -> 4 | I40: =G40+H40 -> 12 | R40: ASM Utilities | S40: 2 | T40: 4 | U40: 6
A41: Mid Florida Contractors | B41: =COUNTIF('Tillman UG Footage'!D:D,"*Mid Florida*") -> 0 | C41: =COUNTIF('Pending Resto-COP Packages'!D:D,"*Mid Florida*") -> 1 | D41: =B41+C41 -> 1 | F41: Wilson | G41: =COUNTIFS('Tillman UG Footage'!F:F,"*"&F41&"*",'Tillman UG Footage'!B:B,"<>AREA") -> 0 | H41: =COUNTIF('Pending Resto-COP Packages'!F:F,"*"&F41&"*") -> 0 | I41: =G41+H41 -> 0 | R41: BICOM | S41: 5 | T41: 2 | U41: 7
A42: R&F Underground | B42: =COUNTIF('Tillman UG Footage'!D:D,"*R&F*") -> 0 | C42: =COUNTIF('Pending Resto-COP Packages'!D:D,"*R&F*") -> 2 | D42: =B42+C42 -> 2 | F42: Efrian | G42: =COUNTIFS('Tillman UG Footage'!F:F,"*"&F42&"*",'Tillman UG Footage'!B:B,"<>AREA") -> 0 | H42: =COUNTIF('Pending Resto-COP Packages'!F:F,"*"&F42&"*") -> 2 | I42: =G42+H42 -> 2 | R42: Brothers | S42: 8 | T42: 16 | U42: 24
A43: NIA Underground | B43: =COUNTIF('Tillman UG Footage'!D:D,"*NIA*") -> 0 | C43: =COUNTIF('Pending Resto-COP Packages'!D:D,"*NIA*") -> 2 | D43: =B43+C43 -> 2 | F43: TOTAL | G43: =SUM(G30:G42) -> 56 | H43: =SUM(H30:H42) -> 84 | I43: =SUM(I30:I42) -> 140 | R43: DMC Boring | S43: 2 | T43: 2 | U43: 4
A44: Alpha Omega | B44: =COUNTIF('Tillman UG Footage'!D:D,"*Alpha Omega*") -> 3 | C44: =COUNTIF('Pending Resto-COP Packages'!D:D,"*Alpha Omega*") -> 2 | D44: =B44+C44 -> 5 | R44: DMG - JOHN | S44: 1 | T44: 0 | U44: 1
A45: J Garcia Underground | B45: =COUNTIF('Tillman UG Footage'!D:D,"*Garcia*") -> 0 | C45: =COUNTIF('Pending Resto-COP Packages'!D:D,"*Garcia*") -> 0 | D45: =B45+C45 -> 0 | R45: Full Circle In-House/Saul/Felipe | S45: 1 | T45: 0 | U45: 1
A46: Splice Only | B46: =COUNTIF('Tillman UG Footage'!D:D,"*Splice*") -> 1 | C46: =COUNTIF('Pending Resto-COP Packages'!D:D,"*Splice*") -> 0 | D46: =B46+C46 -> 1 | R46: GN Systems | S46: 4 | T46: 6 | U46: 10
...

Sheet Raw Data
B1: YTD | C1: JAN | D1: FEB | E1: MARCH | F1: APR | G1: MAY | H1: JUNE | I1: JULY | J1: AUG | K1: SEPT | L1: OCT | M1: NOV | N1: DEC
A2: Total Completed | B2: =SUM(C2:N2) -> 23 | C2: 23
A3: Total Goal | B3: =SUM(C3:N3) -> 13721 | C3: 921 | D3: 11888 | E3: 753 | F3: 159
A4: DOY | B4: =SUM(C4:N4) -> 15 | C4: 15 | D4: 0 | E4: 0 | F4: 0 | G4: 0 | H4: 0 | I4: 0 | J4: 0 | K4: 0 | L4: 0 | M4: 0 | N4: 0
A5: % to Year End | B5: =B4/B8 -> 0.059760956 | C5: =C4/C8 -> 0.68181818 | D5: =D4/D8 -> 0 | E5: =E4/E8 -> 0 | F5: =F4/F8 -> 0 | G5: =G4/G8 -> 0 | H5: =H4/H8 -> 0 | I5: =I4/I8 -> 0 | ... N5: =N4/N8 -> 0
A6: Achieved % to Goal | B6: =B2/B3 -> 0.0016762627 | C6: =C2/C3 -> 0.024972856 | D6: =D2/D3 -> 0 | E6: =E2/E3 -> 0 | F6: =F2/F3 -> 0 | G6: =G2/G3 -> #DIV/0! | H6: =H2/H3 -> #DIV/0! | I6: =I2/I3 -> #DIV/0! | ... N6: =N2/N3 -> #DIV/0!
A7: Total % | B7: 1 | C7: 1 | D7: 1 | E7: 1 | F7: 1 | G7: 1 | H7: 1 | I7: 1 | J7: 1 | K7: 1 | L7: 1 | M7: 1 | N7: 1
B8: 251 | C8: 22 | D8: 20 | E8: 21 | F8: 22 | G8: 22 | H8: 22 | I8: 22 | J8: 22 | K8: 22 | L8: 22 | M8: 22 | N8: 22

Sheet UG Condensed
A1: NTP Number | B1: AREA | C1: SOW TSD Date | D1: Penguin ID | H1: HHP | I1: On Track or In Jeopardy | J1: NTP Received | K1: SOW Received | L1: Permit Status | M1: Door Tag Date | N1: Constuction Status | O1: Locate Date | P1: UG Conduit Status | Q1: Proofing Conduits-ABF Tested | R1: Pulling Fiber | S1: Stingrays | T1: Fiber Spliced | U1: Restoration | V1: Tillman QC Status | W1: COP Package To Biz-Ops Date | X1: Invoice | Y1: {=VLOOKUP(#REF!,#REF!, FALSE)} -> #REF!
A2: BHT-FOE-03 | B2: Bradenton | C2: 45991 | D2: MAN97574 | H2: 0 | J2: Yes | K2: Yes | L2: Received | M2: 45852 | N2: In Process | O2: 45852 | P2: In Process | Q2: In Process | R2: In Process | S2: Not Required | T2: In Process | U2: Pending | V2: Pending
A3: BHUD-FOE-02-W | B3: Bradenton | C3: 45742 | D3: MAN92070 | H3: 0 | J3: Yes | K3: Yes | L3: Received | M3: 45716 | N3: Completed | O3: 45721 | P3: Completed | Q3: Completed | R3: Completed | S3: Not Required | T3: Completed | U3: Completed | V3: Pending | X3: Pending | Y3: =VLOOKUP(A3,#REF!,2,FALSE) -> #REF!
A4: BHUD-FOE-06-E | B4: Bradenton | C4: 45742 | D4: MAN92243 | H4: 0 | J4: Yes | K4: Yes | L4: Received | M4: 45716 | N4: In Process | O4: 45721 | P4: In Process | Q4: In Process | R4: In Process | S4: Not Required | T4: In Process | U4: Pending | V4: Pending | X4: Pending | Y4: =VLOOKUP(A4,#REF!,2,FALSE) -> #REF!
A5: BHZD-FOE-03-W | B5: Bradenton | C5: 45991 | D5: PPM89496 | H5: 0 | J5: Yes | K5: Yes | L5: Received | M5: 45793 | N5: In Process | O5: 45793 | P5: In Process | Q5: In Process | R5: In Process | S5: Not Required | T5: In Process | U5: Pending | V5: Pending | X5: Pending
A6: D-HOE102 | B6: Bradenton | C6: 45747 | D6: MAN89819 | H6: 56 | J6: Yes | K6: Yes | L6: Received | M6: 45701 | N6: Completed | O6: 45718 | P6: Completed | Q6: Completed | R6: Not Req | S6: Completed | T6: Completed | U6: Completed | V6: Pending | X6: Pending | Y6: =VLOOKUP(A6,#REF!,2,FALSE) -> #REF!
A7: D-HOE111 | B7: Bradenton | C7: 45742 | D7: PPM92353 | H7: 60 | J7: Yes | K7: Yes | L7: Received | M7: 45716 | N7: Completed | O7: Completed | P7: Completed | Q7: Completed | R7: Not Req | S7: Completed | T7: Completed | U7: Completed | V7: Pending | X7: Pending | Y7: =VLOOKUP(A7,#REF!,2,FALSE) -> #REF!
A8: D-HOE116 | B8: Bradenton | C8: 45742 | D8: PPM90592 | H8: 84 | J8: Yes | K8: Yes | L8: Received | M8: 45716 | N8: Completed | O8: Completed | P8: Completed | Q8: Completed | R8: Not Req | S8: Completed | T8: Completed | U8: Completed | V8: Pending | X8: Pending | Y8: =VLOOKUP(A8,#REF!,2,FALSE) -> #REF!
A9: D-HOE117 | B9: Bradenton | C9: 45742 | D9: MAN90788 | H9: 79 | J9: Yes | K9: Yes | L9: Received | M9: 45716 | N9: Completed | O9: 45718 | P9: Completed | Q9: Completed | R9: Not Req | S9: Completed | T9: Completed | U9: Completed | V9: Pending | X9: Pending | Y9: =VLOOKUP(A9,#REF!,2,FALSE) -> #REF!
A10: D-HOE120 | B10: Bradenton | C10: 45742 | D10: MAN90778 | H10: 83 | J10: Yes | K10: Yes | L10: Received | M10: 45716 | N10: Completed | O10: Completed | P10: Completed | Q10: Completed | R10: Not Req | S10: Completed | T10: Completed | U10: Completed | V10: Pending | X10: Pending | Y10: =VLOOKUP(A10,#REF!,2,FALSE) -> #REF!
A11: D-HOE206 | B11: Bradenton | C11: 45991 | D11: PPM92353 | E11: 31 | H11: 31 | J11: Yes | K11: Yes | L11: Received | M11: 45716 | N11: In Process | O11: 45716 | P11: Completed | Q11: Completed | R11: Not Req | S11: Completed | T11: Completed | U11: Pending | V11: Pending
A12: D-HOE215 | B12: Bradenton | C12: 45772 | D12: PPM92353 | H12: 31 | J12: Yes | K12: Yes | L12: Received | M12: 45716 | N12: In Process | O12: 45716 | P12: Completed | Q12: Completed | R12: Not Req | S12: Completed | T12: Completed | U12: Pending | V12: Pending | X12: Pending | Y12: =VLOOKUP(A12,#REF!,2,FALSE) -> #REF!
A13: FB-HLR201 | B13: Bradenton | C13: 45960 | D13: MAN98152 | H13: 0 | J13: Yes | K13: Yes | L13: Received | M13: 45867 | N13: In Process | O13: 45867 | P13: In Process | Q13: In Process | R13: In Process | S13: Not Required | T13: In Process | U13: Pending | V13: Pending
A14: D-HOE302 | B14: Bradenton | C14: 45991 | D14: MAN98158 | H14: 57 | J14: Yes | K14: Yes | L14: Received | M14: 45863 | N14: In Process | O14: 45863 | P14: In Process | Q14: In Process | R14: In Process | S14: Not Required | T14: In Process | U14: Pending | V14: Pending
A15: FB-HOE117 | B15: Bradenton | C15: 45711 | D15: MAN89824 | H15: 0 | J15: Yes | K15: Yes | L15: Received | M15: 45701 | N15: Completed | O15: 45718 | P15: Completed | Q15: Completed | R15: Completed | S15: Not Required | T15: Completed | U15: Completed | V15: Completed | W15: 45856 | X15: Submitted | Y15: =VLOOKUP(A15,#REF!,2,FALSE) -> #REF!
A16: FB-HOE201 | B16: Bradenton | C16: 45742 | D16: MAN91981 | H16: 0 | J16: Yes | K16: Yes | L16: Received | M16: 2/29/2025 | N16: Completed | O16: 2/29/2025 | P16: Completed | Q16: Completed | R16: Completed | S16: Not Required | T16: Completed | U16: Pending | V16: Pending | X16: Pending | Y16: =VLOOKUP(A16,#REF!,2,FALSE) -> #REF!
A17: FB-HOE301 | B17: Bradenton | C17: 45991 | D17: MAN98180 | H17: 0 | J17: Yes | K17: Yes | L17: Received | M17: 45863 | N17: Completed | O17: 45863 | P17: Completed | Q17: Completed | R17: Completed | S17: Not Required | T17: Completed | U17: Pending | V17: Pending
A18: FB-HOE375 | B18: Bradenton | C18: 45991 | D18: MAN99383 | H18: 0 | J18: Yes | K18: Yes | L18: Received | M18: 45881 | N18: Completed | O18: 45881 | P18: Completed | Q18: Completed | R18: Completed | S18: Not Required | T18: Completed | U18: Pending | V18: Pending
A19: 12 Oaks MHP | B19: Lakeland | C19: 45899 | H19: 50 | J19: Yes | K19: Yes | L19: Not Required | M19: 45873 | N19: Completed | O19: 45873 | P19: Completed | Q19: Completed | R19: Completed | S19: Not Required | T19: Completed | U19: Completed | V19: Pending
A20: BHT-FWP-06 | B20: Lakeland | C20: 45742 | D20: PLK89457 | H20: 0 | J20: Yes | K20: Yes | L20: Received | M20: 45708 | N20: Completed | O20: 45709 | P20: Completed | Q20: Completed | R20: Completed | S20: Not Required | T20: Completed | U20: Completed | V20: Completed | W20: 45811 | X20: Submitted | Y20: =VLOOKUP(A20,#REF!,2,FALSE) -> #REF!
A21: BHT-FWP-07 | B21: Lakeland | C21: 45772 | D21: PLK91807 | H21: 0 | J21: Yes | K21: Yes | L21: Received | M21: 45708 | N21: Completed | O21: 45737 | P21: Completed | Q21: Completed | R21: Completed | S21: Not Required | T21: Completed | U21: Completed | V21: Completed | W21: 45779 | X21: Submitted | Y21: =VLOOKUP(A21,#REF!,2,FALSE) -> #REF!
A22: BHT-FWP-08 | B22: Lakeland | C22: 45868 | D22: PLK96231 | H22: 0 | J22: Yes | K22: Yes | L22: Received | M22: Not Required | N22: Completed | O22: 45814 | P22: Completed | Q22: Completed | R22: Completed | S22: Not Required | T22: Completed | U22: Completed | V22: Completed | W22: 45848 | X22: Submitted
A23: BHT-FWP-09 | B23: Lakeland | C23: 45838 | D23: PLK95075 | H23: 0 | J23: Yes | K23: Yes | L23: Received | M23: 45786 | N23: Completed | O23: 45789 | P23: Completed | Q23: Completed | R23: Completed | S23: Not Required | T23: Completed | U23: Completed | V23: Completed
A24: BHT-FWP-10 | B24: Lakeland | C24: 45807 | D24: PLK94470 | H24: 0 | J24: Yes | K24: Yes | L24: Received | M24: 45778 | N24: Completed | O24: 45782 | P24: Completed | Q24: Completed | R24: Completed | S24: Not Required | T24: Completed | U24: Completed | V24: Completed | W24: 45826 | X24: Submitted
A25: BHUD-FWP-08-E | B25: Lakeland | C25: 45787 | D25: PLK91306 | H25: 0 | J25: Yes | K25: Yes | L25: Received | M25: 45716 | N25: Completed | O25: 45716 | P25: Completed | Q25: Completed | R25: Completed | S25: Not Required | T25: Completed | U25: Completed | V25: Completed | W25: 45793 | X25: Submitted | Y25: =VLOOKUP(A25,#REF!,2,FALSE) -> #REF!
A26: BHUD-FWP-13-W | B26: Lakeland | C26: 45868 | D26: PLK95092 | H26: 0 | J26: Yes | K26: Yes | L26: Received | M26: Not Required | N26: Completed | O26: 45840 | P26: Completed | Q26: Completed | R26: Completed | S26: Not Required | T26: Completed | U26: Completed | V26: Completed
A27: BHZD-FWP-11-W | B27: Lakeland | C27: 45868 | D27: PLK97102 | H27: 0 | J27: Yes | K27: Yes | L27: Received | M27: Not Required | N27: Completed | O27: 45853 | P27: Completed | Q27: Completed | R27: Completed | S27: Not Required | T27: Completed | U27: Completed | V27: Completed
A28: BHZD-FWP-13-E | B28: Lakeland | C28: 45868 | D28: PLK95389 | H28: 0 | J28: Yes | K28: Yes | L28: Received | M28: 45793 | N28: Completed | O28: 45793 | P28: Completed | Q28: Completed | R28: Completed | S28: Not Required | T28: Completed | U28: Completed | V28: Completed
A29: D-HWP102 | B29: Lakeland | C29: 45711 | D29: MAN91697 | H29: 54 | J29: Yes | K29: Yes | L29: Received | M29: 45659 | N29: Completed | O29: 45692 | P29: Completed | Q29: Completed | R29: Completed | S29: Completed | T29: Completed | U29: Completed | V29: Completed | W29: 45789 | X29: Submitted | Y29: =VLOOKUP(A29,#REF!,2,FALSE) -> #REF!
A30: D-HWP103 | B30: Lakeland | C30: 45711 | D30: PLK88967 | H30: 49 | J30: Yes | K30: Yes | L30: Received | M30: 45713 | N30: Completed | O30: 45692 | P30: Completed | Q30: Completed | R30: Completed | S30: Completed | T30: Completed | U30: Completed | V30: Completed | W30: 45789 | X30: Submitted | Y30: =VLOOKUP(A30,#REF!,2,FALSE) -> #REF!
A31: D-HWP105 | B31: Lakeland | C31: 45716 | D31: PLK90239 | H31: 56 | J31: Yes | K31: Yes | L31: Received | M31: 45707 | N31: Completed | O31: 45707 | P31: Completed | Q31: Completed | R31: Not Req | S31: Completed | T31: Completed | U31: Completed | V31: Completed | W31: 45779 | X31: Submitted | Y31: =VLOOKUP(A31,#REF!,2,FALSE) -> #REF!
A32: D-HWP1304 | B32: Lakeland | C32: 45772 | D32: PLK93497 | H32: 82 | J32: Yes | K32: Yes | L32: Received | M32: 45756 | N32: Completed | O32: 45756 | P32: Completed | Q32: Completed | R32: Not Req | S32: Completed | T32: Completed | U32: Completed | V32: Completed | W32: 45792 | X32: Submitted
A33: D-HWP1306 | B33: Lakeland | C33: 45772 | D33: PLK92368 | H33: 79 | J33: Yes | K33: Yes | L33: Received | M33: 45749 | N33: Completed | O33: 45749 | P33: Completed | Q33: Completed | R33: Not Req | S33: Completed | T33: Completed | U33: Completed | V33: Completed | W33: 45812 | X33: Submitted | Y33: =VLOOKUP(A33,#REF!,2,FALSE) -> #REF!
A34: D-HWP1309 | B34: Lakeland | C34: 45772 | D34: PLK92363 | H34: 59 | J34: Yes | K34: Yes | L34: Received | M34: 45750 | N34: Completed | O34: 45750 | P34: Completed | Q34: Completed | R34: Not Req | S34: Completed | T34: Completed | U34: Completed | V34: Completed | W34: 45797 | X34: Submitted
A35: D-HWP412 | B35: Lakeland | C35: 45688 | D35: PLK87663 | H35: 23 | J35: Yes | K35: Yes | L35: Received | M35: 45659 | N35: Completed | O35: 45659 | P35: Completed | Q35: Completed | R35: Not Req | S35: Completed | T35: Completed | U35: Completed | V35: Completed | W35: 45789 | X35: Submitted | Y35: =VLOOKUP(A35,#REF!,2,FALSE) -> #REF!
A36: D-HWP415 | B36: Lakeland | C36: 45688 | D36: PLK88133 | H36: 70 | J36: Yes | K36: Yes | L36: Received | M36: 45659 | N36: Completed | O36: 45659 | P36: Completed | Q36: Completed | R36: Not Req | S36: Completed | T36: Completed | U36: Completed | V36: Completed | W36: 45824 | X36: Submitted | Y36: =VLOOKUP(A36,#REF!,2,FALSE) -> #REF!
A37: D-HWP425 | B37: Lakeland | C37: 45688 | D37: PLK88584 | H37: 75 | J37: Yes | K37: Yes | L37: Received | M37: Completed | N37: Completed | O37: 45672 | P37: Completed | Q37: Completed | R37: Not Req | S37: Completed | T37: Completed | U37: Completed | V37: Completed | W37: 45789 | X37: Submitted | Y37: =VLOOKUP(A37,#REF!,2,FALSE) -> #REF!
A38: D-HWP436 | B38: Lakeland | C38: 45688 | D38: PLK88375 | H38: 65 | J38: Yes | K38: Yes | L38: Received | M38: 45673 | N38: Completed | O38: 45673 | P38: Completed | Q38: Completed | R38: Not Req | S38: Completed | T38: Completed | U38: Completed | V38: Completed | W38: 45789 | X38: Submitted | Y38: =VLOOKUP(A38,#REF!,2,FALSE) -> #REF!
A39: D-HWP441 | B39: Lakeland | C39: 45688 | D39: PLK88853 | H39: 81 | J39: Yes | K39: Yes | L39: Received | M39: Completed | N39: Completed | O39: 45672 | P39: Completed | Q39: Completed | R39: Not Req | S39: Completed | T39: Completed | U39: Completed | V39: Completed | W39: 45789 | X39: Submitted | Y39: =VLOOKUP(A39,#REF!,2,FALSE) -> #REF!
A40: D-HWP701 | B40: Lakeland | C40: 45742 | D40: PLK89401 | H40: 50 | J40: Yes | K40: Yes | L40: Received | M40: 45705 | N40: Completed | O40: 45715 | P40: Completed | Q40: Completed | R40: Completed | S40: Completed | T40: Completed | U40: Completed | V40: Completed | W40: 45789 | X40: Submitted | Y40: =VLOOKUP(A40,#REF!,2,FALSE) -> #REF!
...

Sheet Completed Jobs Summary
B1: CURRENT ASSIGNMENTS | E1: MONTHLY ASSIGNED FOOTAGE
B2: Sum of Footage UG | E2: Vendor Assignment | F2: (Multiple Items) | P2: On Track or In Jeopardy | Q2: In Jeopardy
B3: Vendor Assignment | C3: Total | K3: Tillman forecasted Month | L3: APRIL | P3: Tillman forecasted Month | Q3: APRIL
B4: Brothers | C4: 53127 | E4: Sum of Footage UG | F4: Total | W4: Working Day | X4: 22
B5: Lightspeed In-House | C5: 12248 | E5: Total | F5: 107526 | K5: Count of Job No | P5: Count of Job No | W5: Day to Month | X5: 13
B6: (blank) | C6: 48410 | K6: On Track or In Jeopardy | L6: Job No | M6: Total | P6: Blockers | Q6: Job No | R6: Total
B7: Vendor Assignment | C7: 0 | K7: In Jeopardy | L7: BHT-FWP-06 | M7: 1 | P7: Manpower | R7: 1 | X7: % Month | Y7: % to Goal
B8: North Path | C8: 42234 | L8: BHT-FWP-07 | M8: 1 | P8: NTP Permit | R8: 1 | V8: Monthly Forecast Footage | W8: 203521 | X8: =X5/X4 -> 0.59090909 | Y8: =W9/W8 -> 0.31446386
B9: GN Systems | C9: 22737 | L9: D-HDH40 | M9: 1 | P9: Tie-ends | Q9: D-HDH40 | R9: 1 | V9: Footage Complete | W9: 64000
B10: Splice Only Project | C10: 3 | L10: D-HDH41 | M10: 1 | Q10: D-HDH42 | R10: 1
B11: Kattle One | C11: 24711 | L11: D-HDH42 | M11: 1 | Q11: D-HDH43 | R11: 1
B12: Kattle One/LSCG | C12: 6182 | L12: D-HDH43 | M12: 1 | Q12: D-HDH51 | R12: 1
B13: APT Communications / New Gen Unlimited | C13: 30807 | L13: D-HDH44 | M13: 1 | Q13: D-HDH62 | R13: 1
B14: Lopez Underground | C14: 58481 | L14: D-HDH50 | M14: 1 | P14: Tie-ends Total | R14: 5
B15: Power Connect | C15: 42151 | L15: D-HDH51 | M15: 1 | P15: (blank) | R15: 12
B16: Alpha Omega | C16: 18823 | L16: D-HDH52 | M16: 1 | P16: Grand Total | R16: 19
B17: HAS Global | C17: 3106 | L17: D-HDH53 | M17: 1
B18: APT Communications | C18: 15600 | L18: D-HDH54 | M18: 1
B19: ASM Utilities | C19: 11043 | L19: D-HDH55 | M19: 1
B20: HD Cable | C20: 16923 | L20: D-HDH57 | M20: 1
B21: Legant Livings | C21: 24336 | L21: D-HDH61 | M21: 1
B22: Gulfstream | C22: 10070 | L22: D-HDH62 | M22: 1
B23: Restoring Pro | C23: 19892 | L23: D-HDH80 | M23: 1
B24: Randy's Utilities | C24: 13494 | L24: FB-HDH02A | M24: 1
B25: A1 Broadband | C25: 13430 | L25: FB-HWP601 | M25: 1
B26: Full Circle In-House/Saul/Felipe | C26: 5350 | K26: In Jeopardy Total | M26: 19
B27: Sosa Line | C27: 7602 | K27: Complete | L27: D-HDH47 | M27: 1
B28: APT Communications/North Path | C28: 9133 | L28: D-HDH48 | M28: 1
B29: ASM | C29: 9260 | L29: D-HDH49 | M29: 1
B30: ITG In-House | C30: 7068 | L30: D-HDH56 | M30: 1
B31: Grand Total | C31: 526221 | L31: D-HDH58 | M31: 1
L32: D-HDH59 | M32: 1
L33: D-HDH60 | M33: 1
L34: D-HDH82 | M34: 1
L35: D-HWP702 | M35: 1
L36: D-HWP703 | M36: 1
L37: D-HWP706 | M37: 1
L38: D-HWP707 | M38: 1
K39: Complete Total | M39: 12
K40: Grand Total | M40: 31

Sheet Project Summary 
H1: D&E Update | Q1: Constuction Status
R2: Prism | S2: Local Team | T2: Penguin Task | U2: Penguin Task | V2: Penguin Task | W2: Penguin Task | X2: PLC | Y2: Noes
A3: Job No | B3: AREA | C3: TSD | D3: HHP | E3: Tillman forecasted Month | F3: Days | G3: On Track or In Jeopardy | H3: Permit Status | I3: Funding | J3: Required Permits | K3: Drafting | L3: Submitted | M3: Approved | N3: Pending Permits | O3: % Complete | P3: Blockers | Q3: Constuction Status | R3: Funding | S3: Materials | T3: Construction Start | U3: UG Percentage Complete | V3: Aerial Percentage Complete | W3: Splicing Percentage Complete | X3: Construction Total Percent Complete | Y3: Additional Information | Z3: Required Footage
A4: FB-HNP104 | B4: St Petersburg | C4: 45807 | E4: APRIL, MAY | G4: In Jeopardy | P4: Locates | Q4: Locates Called | R4: Funded | Z4: =VLOOKUP(A4,#REF!,9,FALSE) -> #REF!
A5: D-HNP107 | B5: St Petersburg | C5: 45807 | E5: APRIL, MAY | G5: In Jeopardy | P5: Locates | Q5: Locates Called | R5: Funded | Z5: =VLOOKUP(A5,#REF!,9,FALSE) -> #REF!
A6: D-HNP106 | B6: St Petersburg | C6: 45807 | E6: APRIL, MAY | G6: In Jeopardy | P6: Locates | Q6: Locates Called | R6: Funded | Z6: =VLOOKUP(A6,#REF!,9,FALSE) -> #REF!
A7: D-HNP110 | B7: St Petersburg | C7: 45807 | E7: APRIL, MAY | G7: In Jeopardy | P7: Locates | Q7: Locates Called | R7: Funded | Z7: =VLOOKUP(A7,#REF!,9,FALSE) -> #REF!
A8: D-HNP109 | B8: St Petersburg | C8: 45807 | E8: APRIL, MAY | G8: In Jeopardy | P8: NTP Permit | Q8: Hold | R8: Missing | Z8: =VLOOKUP(A8,#REF!,9,FALSE) -> #REF!
A9: D-HNP108 | B9: St Petersburg | C9: 45807 | E9: APRIL, MAY | G9: In Jeopardy | P9: Locates | Q9: Locates Called | R9: Funded | Z9: =VLOOKUP(A9,#REF!,9,FALSE) -> #REF!
A10: D-HNP104 | B10: St Petersburg | C10: #N/A | E10: APRIL, MAY | G10: In Jeopardy | P10: Locates | Q10: Not Started | R10: Funded | Z10: =VLOOKUP(A10,#REF!,9,FALSE) -> #REF!
A11: FB-HNP111 | B11: St Petersburg | C11: 45807 | E11: APRIL, MAY | G11: In Jeopardy | P11: Locates | Q11: Locates Called | R11: Funded | Z11: =VLOOKUP(A11,#REF!,9,FALSE) -> #REF!
A12: D-HNP114 | B12: St Petersburg | C12: #N/A | E12: APRIL, MAY | G12: In Jeopardy | P12: Locates | Q12: Locates Called | R12: Funded | Z12: =VLOOKUP(A12,#REF!,9,FALSE) -> #REF!
A13: D-HNP111 | B13: St Petersburg | C13: #N/A | E13: APRIL, MAY | G13: In Jeopardy | P13: Locates | Q13: Locates Called | R13: Funded | Z13: =VLOOKUP(A13,#REF!,9,FALSE) -> #REF!
A14: D-HNP113 | B14: St Petersburg | C14: 45807 | E14: APRIL, MAY | G14: In Jeopardy | P14: Locates | Q14: Locates Called | R14: Funded | Z14: =VLOOKUP(A14,#REF!,9,FALSE) -> #REF!
A15: D-HNP117 | B15: St Petersburg | C15: #N/A | E15: APRIL, MAY | G15: In Jeopardy | P15: Locates | Q15: Locates Called | R15: Funded | Z15: =VLOOKUP(A15,#REF!,9,FALSE) -> #REF!
A16: D-HNP115 | B16: St Petersburg | C16: #N/A | E16: APRIL, MAY | G16: In Jeopardy | P16: Locates | Q16: Locates Called | R16: Funded | Z16: =VLOOKUP(A16,#REF!,9,FALSE) -> #REF!
A17: FB-HDH02A | B17: St Petersburg | C17: #N/A | E17: APRIL | G17: In Jeopardy | Q17: Locates Called | R17: Funded | Z17: =VLOOKUP(A17,#REF!,9,FALSE) -> #REF!
A18: D-HDH80 | B18: St Petersburg | C18: 45807 | E18: APRIL | G18: In Jeopardy | P18: Manpower | R18: Funded | Z18: =VLOOKUP(A18,#REF!,9,FALSE) -> #REF!
A19: D-HDH82 | B19: St Petersburg | C19: #N/A | E19: APRIL | G19: Complete | Q19: Complete | R19: Funded | Z19: =VLOOKUP(A19,#REF!,9,FALSE) -> #REF!
A20: D-HDH47 | B20: St Petersburg | C20: #N/A | E20: APRIL | G20: Complete | Q20: Complete | R20: Funded | Z20: =VLOOKUP(A20,#REF!,9,FALSE) -> #REF!
A21: D-HDH44 | B21: #N/A | C21: 45807 | E21: APRIL | G21: In Jeopardy | Q21: In Process | R21: Funded | Y21: Need to follow-up if we need to place any additional underground conduit for the tie ins | Z21: =VLOOKUP(A21,#REF!,9,FALSE) -> #REF!
A22: D-HDH48 | B22: St Petersburg | C22: #N/A | E22: APRIL | G22: Complete | Q22: Complete | R22: Funded | Z22: =VLOOKUP(A22,#REF!,9,FALSE) -> #REF!
A23: D-HDH41 | B23: St Petersburg | C23: #N/A | E23: APRIL | G23: In Jeopardy | Q23: In Process | R23: Funded | Y23: blowing sting ray 5.1 | Z23: =VLOOKUP(A23,#REF!,9,FALSE) -> #REF!
A24: D-HDH40 | B24: #N/A | C24: 45716 | E24: APRIL | G24: In Jeopardy | P24: Tie-ends | Q24: In Process | R24: Funded | Y24: blowing sting ray 5.1 | Z24: =VLOOKUP(A24,#REF!,9,FALSE) -> #REF!
A25: D-HDH42 | B25: St Petersburg | C25: 45772 | E25: APRIL | G25: In Jeopardy | P25: Tie-ends | Q25: In Process | R25: Funded | Z25: =VLOOKUP(A25,#REF!,9,FALSE) -> #REF!
A26: D-HDH43 | B26: St Petersburg | C26: 45772 | E26: APRIL | G26: In Jeopardy | P26: Tie-ends | Q26: In Process | R26: Funded | Z26: =VLOOKUP(A26,#REF!,9,FALSE) -> #REF!
A27: D-HDH62 | B27: St Petersburg | C27: 45772 | E27: APRIL | G27: In Jeopardy | P27: Tie-ends | Q27: In Process | R27: Funded | Z27: =VLOOKUP(A27,#REF!,9,FALSE) -> #REF!
A28: D-HDH51 | E28: APRIL | G28: In Jeopardy | P28: Tie-ends | Q28: In Process | R28: Funded | Y28: Need to follow-up if we need to place any additional underground conduit for the tie ins | Z28: =VLOOKUP(A28,#REF!,9,FALSE) -> #REF!
A29: D-HDH61 | B29: #N/A | C29: #N/A | E29: APRIL | G29: In Jeopardy | Q29: In Process | R29: Funded | Y29: Need to follow-up if we need to place any additional underground conduit for the tie ins | Z29: =VLOOKUP(A29,#REF!,9,FALSE) -> #REF!
A30: D-HDH56 | B30: St Petersburg | C30: 45772 | E30: APRIL | G30: Complete | Q30: Complete | R30: Funded | Z30: =VLOOKUP(A30,#REF!,9,FALSE) -> #REF!
A31: D-HDH60 | B31: St Petersburg | C31: 45772 | E31: APRIL | G31: Complete | Q31: Complete | R31: Funded | Y31: Pending: confirm rock adder w/ Tillman Inspector to complete measurements | Z31: =VLOOKUP(A31,#REF!,9,FALSE) -> #REF!
A32: D-HDH58 | B32: St Petersburg | C32: 45772 | E32: APRIL | G32: Complete | Q32: Complete | R32: Funded | Z32: =VLOOKUP(A32,#REF!,9,FALSE) -> #REF!
A33: D-HDH53 | B33: St Petersburg | C33: 45831 | E33: APRIL | G33: In Jeopardy | Q33: In Process | R33: Funded | Z33: =VLOOKUP(A33,#REF!,9,FALSE) -> #REF!
A34: D-HDH50 | B34: St Petersburg | C34: 45831 | E34: APRIL | G34: In Jeopardy | Q34: In Process | R34: Funded | Z34: =VLOOKUP(A34,#REF!,9,FALSE) -> #REF!
A35: D-HDH52 | B35: St Petersburg | C35: 45831 | E35: APRIL | G35: In Jeopardy | Q35: In Process | R35: Funded | Z35: =VLOOKUP(A35,#REF!,9,FALSE) -> #REF!
A36: D-HDH49 | B36: St Petersburg | C36: 45772 | E36: APRIL | G36: Complete | Q36: Complete | R36: Funded | Z36: =VLOOKUP(A36,#REF!,9,FALSE) -> #REF!
A37: D-HDH54 | B37: St Petersburg | C37: 45831 | E37: APRIL | G37: In Jeopardy | Q37: In Process | R37: Funded | Z37: =VLOOKUP(A37,#REF!,9,FALSE) -> #REF!
A38: D-HDH55 | B38: St Petersburg | C38: 45831 | E38: APRIL | G38: In Jeopardy | Q38: In Process | R38: Funded | Z38: =VLOOKUP(A38,#REF!,9,FALSE) -> #REF!
A39: D-HDH59 | B39: #N/A | C39: #N/A | E39: APRIL | G39: Complete | Q39: Complete | R39: Funded | Y39: Need to follow-up if we need to place any additional underground conduit for the tie ins | Z39: =VLOOKUP(A39,#REF!,9,FALSE) -> #REF!
A40: D-HDH57 | B40: St Petersburg | C40: 45831 | E40: APRIL | G40: In Jeopardy | Q40: In Process | R40: Funded | Z40: =VLOOKUP(A40,#REF!,9,FALSE) -> #REF!
...

Sheet Tillman UG Footage
A1: Market 1 NTP Number | B1: AREA | C1: SOW TSD Date | D1: Vendor Assignment | E1: Date Assigned | F1: Assigned Supervisor | G1: Penguin ID | H1: HHP | I1: On Track or In Jeopardy | J1: Permit Status | K1: Blockers/Risks | L1: Door Tag Date | M1: SOW Received | N1: SOW Estimated Cost | O1: NTP Received | P1: Constuction Status | Q1: Locate Date | R1: Restoration Completed | S1: QC Requested Date | T1: QC Sheet Phase 1 Received | U1: QC Sheet Phase 2 Received | V1: Footage UG | W1: Actual Redline Completed Footage UG | X1: Footage Remaining | Y1: UG Percentage Complete | Z1: Construction Start Date | AA1: Construction End Date | AB1: Fiber Placement Percentage Complete | AC1: Splicing Percentage Complete | AD1: Fiber Placement and Splice Only Footage | AE1: Notes
A2: D-HPP630 | B2: Clearwater | C2: 46325 | D2: Brothers | E2: 46171 | F2: Marcelo Zaldivar | H2: 67 | I2: On Track | J2: Received | M2: Yes | N2: 100866 | O2: Yes | P2: Completed | Q2: 46175 | V2: 9021 | W2: 8341 | X2: =SUM(V2-W2) -> 680 | Y2: =IFERROR($W2/$V2, 0) -> 0.92462033 | Z2: 46195 | AA2: 46230 | AB2: 0 | AC2: 0 | AD2: 0 | AE2: 5/1 NTP Package Received.
A3: D-HPP631 | B3: Clearwater | C3: 46325 | D3: Brothers | E3: 46170 | F3: Treyvon Tillman | H3: 93 | I3: On Track | J3: Received | M3: Yes | N3: 104934 | O3: Yes | P3: Completed | Q3: 46176 | V3: 8701 | W3: 7811 | X3: =SUM(V3-W3) -> 890 | Y3: =IFERROR($W3/$V3, 0) -> 0.89771291 | Z3: 46191 | AA3: 46261 | AB3: 0 | AC3: 0 | AD3: 0 | AE3: 5/1 NTP Package Received.
A4: D-HPP637 | B4: Clearwater | C4: 46325 | D4: Lightspeed In-House | E4: 46171 | F4: Treyvon Tillman | H4: 40 | I4: On Track | J4: Received | L4: 46182 | M4: Yes | N4: 91774 | O4: Yes | P4: In Process | Q4: 46171 | V4: 7530 | W4: 7204 | X4: =SUM(V4-W4) -> 326 | Y4: =IFERROR($W4/$V4, 0) -> 0.95670651 | Z4: 46217 | AB4: 0 | AC4: 0 | AD4: 0 | AE4: 5/1 NTP Package Received.
A5: FB-HPP612-2 | B5: Clearwater | C5: 46305 | F5: Anthony Adum | H5: 0 | I5: On Track | J5: Received | M5: No | N5: 649 | O5: Yes | P5: Not Started | V5: 0 | X5: =SUM(V5-W5) -> 0 | Y5: =IFERROR($W5/$V5, 0) -> 0 | AB5: 0 | AC5: 0 | AD5: 0 | AE5: 9/23 NTP Package Received--PO In Full Circle's Name Not ITG--Tillman Needs To Upload A New PO. Aerial Work Project.
A6: D-HNP108/D-H0102E | B6: St Petersburg | C6: 46080 | D6: Kattle One/LSCG | E6: 46018 | F6: Johnnie Williams | G6: PPM91941 | H6: 89 | I6: On Track | J6: Received | L6: 46028 | M6: Yes | N6: 72131.5 | O6: Yes | P6: In Process | Q6: 46014 | V6: 6182 | W6: 5899 | X6: =SUM(V6-W6) -> 283 | Y6: =IFERROR($W6/$V6, 0) -> 0.95422193 | Z6: 45891 | AB6: 0 | AC6: 0 | AD6: 0 | AE6: 5/11 - Stop work in place for City of St. Pete till 5/15 - 5/4 Will have to redrill 380' K1 drilled to deep and did not install the 2 tobys, Locates Called in - 4-28 JW // REPAIRED 1 OF 2 DAPs. NEED TO FIND ISSUE WITH THE 2ND DAP LOCATION - 3.16 JW // LSCG QC discovered missing section of Route 2, called in locates and they are pending
A9: Market 1 NTP Number Pinellas | B9: AREA | C9: SOW TSD Date | D9: Vendor Assignment | E9: Date Assigned | F9: Assigned Supervisor | G9: Penguin ID | H9: HHP | I9: On Track or In Jeopardy | J9: Permit Status | K9: Blockers/Risks | L9: Door Tag Date | M9: SOW Received | N9: SOW Estimated Cost | O9: NTP Received | P9: Constuction Status | Q9: Locate Date | R9: Restoration Completed | S9: QC Requested Date | T9: QC Sheet Phase 1 Received | U9: QC Sheet Phase 2 Received | V9: Footage UG | W9: Actual Redline Completed Footage UG | X9: Footage Remaining | Y9: UG Percentage Complete | Z9: Construction Start Date | AA9: Construction End Date | AB9: Fiber Placement Percentage Complete | AC9: Splicing Percentage Complete | AD9: Fiber Placement and Splice Only Footage | AE9: Notes
A10: D-HLC505 | B10: Pinellas | C10: 46325 | D10: Brothers | E10: 46295 | F10: Joshua Pacheco | H10: 41 | I10: On Track | J10: Received | K10: Pending Locates | L10: 46225 | M10: Yes | N10: 78963.5 | O10: Yes | P10: Locates Called | Q10: 46225 | V10: 5973 | X10: =SUM(V10-W10) -> 5973 | Y10: =IFERROR($W10/$V10, 0) -> 0 | AB10: 0 | AC10: 0 | AD10: 0 | AE10: 7/13 NTP Package Received. 7/17 PO Received And Approved.
A11: D-HLC508 | B11: Pinellas | C11: 46295 | D11: ASM Utilities | E11: 46223 | F11: Danny Combs | H11: 69 | I11: Completed -Missed TSD | J11: Received | M11: Yes | N11: 84458.5 | O11: Yes | P11: Completed | Q11: 46230 | V11: 6831 | W11: 5274 | X11: =SUM(V11-W11) -> 1557 | Y11: =IFERROR($W11/$V11, 0) -> 0.77206851 | Z11: 46281 | AA11: 46296 | AB11: 1 | AC11: 1 | AD11: 0 | AE11: 7/13 NTP Package Received. 7/17 PO Received And Approved.
A12: D-HLC509 | B12: Pinellas | C12: 46325 | D12: Brothers | E12: 46288 | F12: Anthony Adum | H12: 72 | I12: On Track | J12: Received | K12: Pending Locates | M12: No | N12: 69525.5 | O12: Yes | P12: Locates Called | Q12: 46288 | V12: 5407 | X12: =SUM(V12-W12) -> 5407 | Y12: =IFERROR($W12/$V12, 0) -> 0 | AB12: 0 | AC12: 0 | AD12: 0 | AE12: 9/18 NTP Package Received. PO Approved 9/24.
A13: D-HLC510 | B13: Pinellas | C13: 46325 | D13: Lightspeed In-House | E13: 46223 | F13: Treyvon Tillman | H13: 102 | I13: On Track | J13: Received | L13: 46224 | M13: Yes | N13: 59181 | O13: Yes | P13: In Process | Q13: 46230 | V13: 4718 | W13: 3520 | X13: =SUM(V13-W13) -> 1198 | Y13: =IFERROR($W13/$V13, 0) -> 0.74607885 | Z13: 46283 | AB13: 0 | AC13: 0 | AD13: 0 | AE13: 7/13 NTP Package Received. 7/17 PO Received And Approved.
